<robot
  name="tensegrity">
  <link
    name="tensegrity">
    <inertial>
      <origin
        xyz="-0.022792 0.027255 0.87612"
        rpy="0 0 0" />
      <mass
        value="3.0323" />
      <inertia
        ixx="1.5711"
        ixy="0.0062699"
        ixz="-0.0013653"
        iyy="1.5845"
        iyz="0.0048794"
        izz="0.17331" />
    </inertial>
    <visual>
      <origin
        xyz="0 0 0"
        rpy="0 0 0" />
      <geometry>
        <mesh
          filename="package://tensegrity/meshes/tensegrity.STL" />
      </geometry>
      <material
        name="">
        <color
          rgba="0.79216 0.81961 0.93333 1" />
      </material>
    </visual>
    <collision>
      <origin
        xyz="0 0 0"
        rpy="0 0 0" />
      <geometry>
        <mesh
          filename="package://tensegrity/meshes/tensegrity.STL" />
      </geometry>
    </collision>
  </link>
  <link
    name="tightener1">
    <inertial>
      <origin
        xyz="-0.0112648807710245 -0.00441342960711988 0.00969743752472763"
        rpy="0 0 0" />
      <mass
        value="0.0085646299641912" />
      <inertia
        ixx="9.48346301710473E-07"
        ixy="4.66685161768179E-07"
        ixz="5.01471138407434E-07"
        iyy="3.09043873265829E-06"
        iyz="1.90238552895541E-07"
        izz="2.8436839812627E-06" />
    </inertial>
    <visual>
      <origin
        xyz="0 0 0"
        rpy="0 0 0" />
      <geometry>
        <mesh
          filename="package://tensegrity/meshes/tightener1.STL" />
      </geometry>
      <material
        name="">
        <color
          rgba="1 0.168627450980392 0.168627450980392 1" />
      </material>
    </visual>
    <collision>
      <origin
        xyz="0 0 0"
        rpy="0 0 0" />
      <geometry>
        <mesh
          filename="package://tensegrity/meshes/tightener1.STL" />
      </geometry>
    </collision>
  </link>
  <joint
    name="tightener1"
    type="fixed">
    <origin
      xyz="-0.0261159197978372 0.399512764329084 1.43386111414929"
      rpy="0.181319774401501 0 3.14159265358979" />
    <parent
      link="tensegrity" />
    <child
      link="tightener1" />
    <axis
      xyz="0 0 0" />
  </joint>
  <link
    name="tightener2">
    <inertial>
      <origin
        xyz="-0.0112649023815932 -0.00441338917167455 0.00969744047796206"
        rpy="0 0 0" />
      <mass
        value="0.00856464520084467" />
      <inertia
        ixx="9.48345554667794E-07"
        ixy="4.66676495816749E-07"
        ixz="5.01469301430554E-07"
        iyy="3.0904428656793E-06"
        iyz="1.90238499470877E-07"
        izz="2.84368695035454E-06" />
    </inertial>
    <visual>
      <origin
        xyz="0 0 0"
        rpy="0 0 0" />
      <geometry>
        <mesh
          filename="package://tensegrity/meshes/tightener2.STL" />
      </geometry>
      <material
        name="">
        <color
          rgba="1 0.168627450980392 0.168627450980392 1" />
      </material>
    </visual>
    <collision>
      <origin
        xyz="0 0 0"
        rpy="0 0 0" />
      <geometry>
        <mesh
          filename="package://tensegrity/meshes/tightener2.STL" />
      </geometry>
    </collision>
  </link>
  <joint
    name="tightener2"
    type="fixed">
    <origin
      xyz="-0.421921414642284 -0.075053824261462 1.26479790365546"
      rpy="-1.82448281699546 0.769136226420718 -0.178410499351035" />
    <parent
      link="tensegrity" />
    <child
      link="tightener2" />
    <axis
      xyz="0 0 0" />
  </joint>
  <link
    name="tightener3">
    <inertial>
      <origin
        xyz="-0.0112649042192468 -0.00441343288623197 0.00969743422688466"
        rpy="0 0 0" />
      <mass
        value="0.00856463183459587" />
      <inertia
        ixx="9.48348547824724E-07"
        ixy="4.66688007253631E-07"
        ixz="5.01471990198088E-07"
        iyy="3.09044823930531E-06"
        iyz="1.90239037244571E-07"
        izz="2.84369551495927E-06" />
    </inertial>
    <visual>
      <origin
        xyz="0 0 0"
        rpy="0 0 0" />
      <geometry>
        <mesh
          filename="package://tensegrity/meshes/tightener3.STL" />
      </geometry>
      <material
        name="">
        <color
          rgba="1 0.168627450980392 0.168627450980392 1" />
      </material>
    </visual>
    <collision>
      <origin
        xyz="0 0 0"
        rpy="0 0 0" />
      <geometry>
        <mesh
          filename="package://tensegrity/meshes/tightener3.STL" />
      </geometry>
    </collision>
  </link>
  <joint
    name="tightener3"
    type="fixed">
    <origin
      xyz="-0.0203759197978371 -0.338397727474194 1.56798570431322"
      rpy="1.57079632679489 1.3894765523934 -1.5707963267949" />
    <parent
      link="tensegrity" />
    <child
      link="tightener3" />
    <axis
      xyz="0 0 0" />
  </joint>
  <link
    name="tightener4">
    <inertial>
      <origin
        xyz="-0.0112649039981367 -0.00441345106264546 0.00969743300736436"
        rpy="0 0 0" />
      <mass
        value="0.00856463280589166" />
      <inertia
        ixx="9.4835070565726E-07"
        ixy="4.66692396032687E-07"
        ixz="5.01472185591982E-07"
        iyy="3.09044783790187E-06"
        iyz="1.90239467213097E-07"
        izz="2.84369724363852E-06" />
    </inertial>
    <visual>
      <origin
        xyz="0 0 0"
        rpy="0 0 0" />
      <geometry>
        <mesh
          filename="package://tensegrity/meshes/tightener4.STL" />
      </geometry>
      <material
        name="">
        <color
          rgba="1 0.168627450980392 0.168627450980392 1" />
      </material>
    </visual>
    <collision>
      <origin
        xyz="0 0 0"
        rpy="0 0 0" />
      <geometry>
        <mesh
          filename="package://tensegrity/meshes/tightener4.STL" />
      </geometry>
    </collision>
  </link>
  <joint
    name="tightener4"
    type="fixed">
    <origin
      xyz="-0.315855397464302 -0.0514025752621537 1.36829562546987"
      rpy="1.31710983659433 0.769136226420718 -0.178410499351035" />
    <parent
      link="tensegrity" />
    <child
      link="tightener4" />
    <axis
      xyz="0 0 0" />
  </joint>
  <link
    name="tightener5">
    <inertial>
      <origin
        xyz="-0.0112649434483725 -0.0044133076771109 0.00969746072280264"
        rpy="0 0 0" />
      <mass
        value="0.00856464027785634" />
      <inertia
        ixx="9.48335413159062E-07"
        ixy="4.66656916939354E-07"
        ixz="5.0146610955254E-07"
        iyy="3.09045336216761E-06"
        iyz="1.90235224144569E-07"
        izz="2.84368908467754E-06" />
    </inertial>
    <visual>
      <origin
        xyz="0 0 0"
        rpy="0 0 0" />
      <geometry>
        <mesh
          filename="package://tensegrity/meshes/tightener5.STL" />
      </geometry>
      <material
        name="">
        <color
          rgba="1 0.168627450980392 0.168627450980392 1" />
      </material>
    </visual>
    <collision>
      <origin
        xyz="0 0 0"
        rpy="0 0 0" />
      <geometry>
        <mesh
          filename="package://tensegrity/meshes/tightener5.STL" />
      </geometry>
    </collision>
  </link>
  <joint
    name="tightener5"
    type="fixed">
    <origin
      xyz="0.107602569517075 0.0263707341619003 1.78619185869198"
      rpy="-0.785398163397445 0.181319774401482 1.5707963267949" />
    <parent
      link="tensegrity" />
    <child
      link="tightener5" />
    <axis
      xyz="0 0 0" />
  </joint>
  <link
    name="tightener6">
    <inertial>
      <origin
        xyz="-0.0112648753943836 -0.00441343060605393 0.00969743601282969"
        rpy="0 0 0" />
      <mass
        value="0.00856463401560633" />
      <inertia
        ixx="9.4834699396603E-07"
        ixy="4.66685035810979E-07"
        ixz="5.01471107260595E-07"
        iyy="3.09043623385797E-06"
        iyz="1.90238686898358E-07"
        izz="2.84368201569958E-06" />
    </inertial>
    <visual>
      <origin
        xyz="0 0 0"
        rpy="0 0 0" />
      <geometry>
        <mesh
          filename="package://tensegrity/meshes/tightener6.STL" />
      </geometry>
      <material
        name="">
        <color
          rgba="1 0.168627450980392 0.168627450980392 1" />
      </material>
    </visual>
    <collision>
      <origin
        xyz="0 0 0"
        rpy="0 0 0" />
      <geometry>
        <mesh
          filename="package://tensegrity/meshes/tightener6.STL" />
      </geometry>
    </collision>
  </link>
  <joint
    name="tightener6"
    type="fixed">
    <origin
      xyz="-0.0249759197978372 -0.190856743867637 1.54093652398535"
      rpy="-1.5707963267949 1.3894765523934 -1.5707963267949" />
    <parent
      link="tensegrity" />
    <child
      link="tightener6" />
    <axis
      xyz="0 0 0" />
  </joint>
  <link
    name="tightener7">
    <inertial>
      <origin
        xyz="-0.011264875967715 -0.00441343717059595 0.00969743225970313"
        rpy="0 0 0" />
      <mass
        value="0.00856463670998747" />
      <inertia
        ixx="9.48347440075865E-07"
        ixy="4.66686405885412E-07"
        ixz="5.01471905064638E-07"
        iyy="3.09043582663768E-06"
        iyz="1.90238697252733E-07"
        izz="2.84368197914388E-06" />
    </inertial>
    <visual>
      <origin
        xyz="0 0 0"
        rpy="0 0 0" />
      <geometry>
        <mesh
          filename="package://tensegrity/meshes/tightener7.STL" />
      </geometry>
      <material
        name="">
        <color
          rgba="1 0.168627450980392 0.168627450980392 1" />
      </material>
    </visual>
    <collision>
      <origin
        xyz="0 0 0"
        rpy="0 0 0" />
      <geometry>
        <mesh
          filename="package://tensegrity/meshes/tightener7.STL" />
      </geometry>
    </collision>
  </link>
  <joint
    name="tightener7"
    type="fixed">
    <origin
      xyz="-0.0476944936653156 0.124010188129215 1.65963797124096"
      rpy="-1.31710983659433 0.769136226420716 -2.96318215423875" />
    <parent
      link="tensegrity" />
    <child
      link="tightener7" />
    <axis
      xyz="0 0 0" />
  </joint>
  <link
    name="tightener8">
    <inertial>
      <origin
        xyz="-0.0112649294380096 -0.00441339808548946 0.00969743311534382"
        rpy="0 0 0" />
      <mass
        value="0.00856465792468872" />
      <inertia
        ixx="9.48345449564173E-07"
        ixy="4.66677519510103E-07"
        ixz="5.01470596503646E-07"
        iyy="3.09044836028256E-06"
        iyz="1.90238351816122E-07"
        izz="2.84369196118561E-06" />
    </inertial>
    <visual>
      <origin
        xyz="0 0 0"
        rpy="0 0 0" />
      <geometry>
        <mesh
          filename="package://tensegrity/meshes/tightener8.STL" />
      </geometry>
      <material
        name="">
        <color
          rgba="1 0.168627450980392 0.168627450980392 1" />
      </material>
    </visual>
    <collision>
      <origin
        xyz="0 0 0"
        rpy="0 0 0" />
      <geometry>
        <mesh
          filename="package://tensegrity/meshes/tightener8.STL" />
      </geometry>
    </collision>
  </link>
  <joint
    name="tightener8"
    type="fixed">
    <origin
      xyz="-0.153760510843298 0.138612256800654 1.76479470944882"
      rpy="1.82448281699547 0.769136226420715 -2.96318215423875" />
    <parent
      link="tensegrity" />
    <child
      link="tightener8" />
    <axis
      xyz="0 0 0" />
  </joint>
  <link
    name="tightener9">
    <inertial>
      <origin
        xyz="-0.0112649161265736 -0.00441336591154329 0.009697452591795"
        rpy="0 0 0" />
      <mass
        value="0.00856463882730575" />
      <inertia
        ixx="9.48340756137031E-07"
        ixy="4.6667007953783E-07"
        ixz="5.0146728722652E-07"
        iyy="3.09044692123588E-06"
        iyz="1.90237191683969E-07"
        izz="2.84368718796665E-06" />
    </inertial>
    <visual>
      <origin
        xyz="0 0 0"
        rpy="0 0 0" />
      <geometry>
        <mesh
          filename="package://tensegrity/meshes/tightener9.STL" />
      </geometry>
      <material
        name="">
        <color
          rgba="1 0.168627450980392 0.168627450980392 1" />
      </material>
    </visual>
    <collision>
      <origin
        xyz="0 0 0"
        rpy="0 0 0" />
      <geometry>
        <mesh
          filename="package://tensegrity/meshes/tightener9.STL" />
      </geometry>
    </collision>
  </link>
  <joint
    name="tightener9"
    type="fixed">
    <origin
      xyz="0.377375676777166 0.0487702268702811 1.24291636437404"
      rpy="0.785398163397445 0.181319774401485 1.5707963267949" />
    <parent
      link="tensegrity" />
    <child
      link="tightener9" />
    <axis
      xyz="0 0 0" />
  </joint>
  <link
    name="detach1">
    <inertial>
      <origin
        xyz="0.0136167294130276 0.00336313260997943 -0.00458859078875906"
        rpy="0 0 0" />
      <mass
        value="0.00144131652160448" />
      <inertia
        ixx="2.70919111337064E-08"
        ixy="8.31072147902917E-09"
        ixz="-3.6018362608296E-10"
        iyy="7.19839637780113E-08"
        iyz="-9.28387661696953E-11"
        izz="7.6586247123843E-08" />
    </inertial>
    <visual>
      <origin
        xyz="0 0 0"
        rpy="0 0 0" />
      <geometry>
        <mesh
          filename="package://tensegrity/meshes/detach1.STL" />
      </geometry>
      <material
        name="">
        <color
          rgba="1 0.168627450980392 0.168627450980392 1" />
      </material>
    </visual>
    <collision>
      <origin
        xyz="0 0 0"
        rpy="0 0 0" />
      <geometry>
        <mesh
          filename="package://tensegrity/meshes/detach1.STL" />
      </geometry>
    </collision>
  </link>
  <joint
    name="detach1"
    type="fixed">
    <origin
      xyz="-0.00267591979783716 0.466730797115997 1.44420947480502"
      rpy="0 -0.181319774401501 -1.5707963267949" />
    <parent
      link="tensegrity" />
    <child
      link="detach1" />
    <axis
      xyz="0 0 0" />
  </joint>
  <link
    name="detach2">
    <inertial>
      <origin
        xyz="-0.0321332705869715 0.0268031326099796 -0.0178885907887605"
        rpy="0 0 0" />
      <mass
        value="0.00144131652160448" />
      <inertia
        ixx="2.70919111337063E-08"
        ixy="8.3107214790287E-09"
        ixz="-3.60183626082459E-10"
        iyy="7.19839637780107E-08"
        iyz="-9.28387661696798E-11"
        izz="7.65862471238423E-08" />
    </inertial>
    <visual>
      <origin
        xyz="0 0 0"
        rpy="0 0 0" />
      <geometry>
        <mesh
          filename="package://tensegrity/meshes/detach2.STL" />
      </geometry>
      <material
        name="">
        <color
          rgba="1 0.168627450980392 0.168627450980392 1" />
      </material>
    </visual>
    <collision>
      <origin
        xyz="0 0 0"
        rpy="0 0 0" />
      <geometry>
        <mesh
          filename="package://tensegrity/meshes/detach2.STL" />
      </geometry>
    </collision>
  </link>
  <joint
    name="detach2"
    type="fixed">
    <origin
      xyz="-0.421921414642284 -0.075053824261462 1.26479790365546"
      rpy="1.31710983659433 -0.769136226420714 0.178410499351039" />
    <parent
      link="tensegrity" />
    <child
      link="detach2" />
    <axis
      xyz="0 0 0" />
  </joint>
  <link
    name="detach3">
    <inertial>
      <origin
        xyz="0.0136167294130277 0.00336313260997945 -0.00458859078875877"
        rpy="0 0 0" />
      <mass
        value="0.00144131652160448" />
      <inertia
        ixx="2.70919111337066E-08"
        ixy="8.31072147902924E-09"
        ixz="-3.60183626082437E-10"
        iyy="7.1983963778012E-08"
        iyz="-9.28387661696761E-11"
        izz="7.65862471238438E-08" />
    </inertial>
    <visual>
      <origin
        xyz="0 0 0"
        rpy="0 0 0" />
      <geometry>
        <mesh
          filename="package://tensegrity/meshes/detach3.STL" />
      </geometry>
      <material
        name="">
        <color
          rgba="1 0.168627450980392 0.168627450980392 1" />
      </material>
    </visual>
    <collision>
      <origin
        xyz="0 0 0"
        rpy="0 0 0" />
      <geometry>
        <mesh
          filename="package://tensegrity/meshes/detach3.STL" />
      </geometry>
    </collision>
  </link>
  <joint
    name="detach3"
    type="fixed">
    <origin
      xyz="-0.0336759197978377 -0.379170842228293 1.59929144201814"
      rpy="1.5707963267949 0.181319774401488 1.5707963267949" />
    <parent
      link="tensegrity" />
    <child
      link="detach3" />
    <axis
      xyz="0 0 0" />
  </joint>
  <link
    name="detach4">
    <inertial>
      <origin
        xyz="0.0136167294130277 0.00336313260997922 -0.00458859078875873"
        rpy="0 0 0" />
      <mass
        value="0.00144131652160448" />
      <inertia
        ixx="2.70919111337063E-08"
        ixy="8.31072147902877E-09"
        ixz="-3.60183626082373E-10"
        iyy="7.1983963778011E-08"
        iyz="-9.28387661697087E-11"
        izz="7.65862471238426E-08" />
    </inertial>
    <visual>
      <origin
        xyz="0 0 0"
        rpy="0 0 0" />
      <geometry>
        <mesh
          filename="package://tensegrity/meshes/detach4.STL" />
      </geometry>
      <material
        name="">
        <color
          rgba="1 0.168627450980392 0.168627450980392 1" />
      </material>
    </visual>
    <collision>
      <origin
        xyz="0 0 0"
        rpy="0 0 0" />
      <geometry>
        <mesh
          filename="package://tensegrity/meshes/detach4.STL" />
      </geometry>
    </collision>
  </link>
  <joint
    name="detach4"
    type="fixed">
    <origin
      xyz="-0.377861591106548 -0.0785407278054665 1.34393297523359"
      rpy="1.31710983659433 -0.769136226420712 0.178410499351048" />
    <parent
      link="tensegrity" />
    <child
      link="detach4" />
    <axis
      xyz="0 0 0" />
  </joint>
  <link
    name="detach5">
    <inertial>
      <origin
        xyz="0.0136167294130278 0.00336313260997961 -0.00458859078875862"
        rpy="0 0 0" />
      <mass
        value="0.00144131652160446" />
      <inertia
        ixx="2.7091911133706E-08"
        ixy="8.31072147902952E-09"
        ixz="-3.60183626082243E-10"
        iyy="7.19839637780108E-08"
        iyz="-9.28387661698286E-11"
        izz="7.65862471238427E-08" />
    </inertial>
    <visual>
      <origin
        xyz="0 0 0"
        rpy="0 0 0" />
      <geometry>
        <mesh
          filename="package://tensegrity/meshes/detach5.STL" />
      </geometry>
      <material
        name="">
        <color
          rgba="1 0.168627450980392 0.168627450980392 1" />
      </material>
    </visual>
    <collision>
      <origin
        xyz="0 0 0"
        rpy="0 0 0" />
      <geometry>
        <mesh
          filename="package://tensegrity/meshes/detach5.STL" />
      </geometry>
    </collision>
  </link>
  <joint
    name="detach5"
    type="fixed">
    <origin
      xyz="0.13726569898783 0.0143510786049931 1.85061555565431"
      rpy="0.253686490200554 0.769136226420712 -2.96318215423876" />
    <parent
      link="tensegrity" />
    <child
      link="detach5" />
    <axis
      xyz="0 0 0" />
  </joint>
  <link
    name="detach6">
    <inertial>
      <origin
        xyz="0.0136167294130276 0.00336313260997878 -0.00458859078875878"
        rpy="0 0 0" />
      <mass
        value="0.00144131652160448" />
      <inertia
        ixx="2.70919111337065E-08"
        ixy="8.3107214790292E-09"
        ixz="-3.60183626082489E-10"
        iyy="7.19839637780119E-08"
        iyz="-9.28387661696828E-11"
        izz="7.65862471238436E-08" />
    </inertial>
    <visual>
      <origin
        xyz="0 0 0"
        rpy="0 0 0" />
      <geometry>
        <mesh
          filename="package://tensegrity/meshes/detach6.STL" />
      </geometry>
      <material
        name="">
        <color
          rgba="1 0.168627450980392 0.168627450980392 1" />
      </material>
    </visual>
    <collision>
      <origin
        xyz="0 0 0"
        rpy="0 0 0" />
      <geometry>
        <mesh
          filename="package://tensegrity/meshes/detach6.STL" />
      </geometry>
    </collision>
  </link>
  <joint
    name="detach6"
    type="fixed">
    <origin
      xyz="-0.00267591979783714 -0.249826579933211 1.57557832726404"
      rpy="1.5707963267949 0.181319774401488 1.5707963267949" />
    <parent
      link="tensegrity" />
    <child
      link="detach6" />
    <axis
      xyz="0 0 0" />
  </joint>
  <link
    name="detach7">
    <inertial>
      <origin
        xyz="0.0136167294130272 0.00336313260997945 -0.00458859078875878"
        rpy="0 0 0" />
      <mass
        value="0.00144131652160447" />
      <inertia
        ixx="2.70919111337061E-08"
        ixy="8.31072147902913E-09"
        ixz="-3.60183626082338E-10"
        iyy="7.19839637780109E-08"
        iyz="-9.28387661696475E-11"
        izz="7.65862471238425E-08" />
    </inertial>
    <visual>
      <origin
        xyz="0 0 0"
        rpy="0 0 0" />
      <geometry>
        <mesh
          filename="package://tensegrity/meshes/detach7.STL" />
      </geometry>
      <material
        name="">
        <color
          rgba="1 0.168627450980392 0.168627450980392 1" />
      </material>
    </visual>
    <collision>
      <origin
        xyz="0 0 0"
        rpy="0 0 0" />
      <geometry>
        <mesh
          filename="package://tensegrity/meshes/detach7.STL" />
      </geometry>
    </collision>
  </link>
  <joint
    name="detach7"
    type="fixed">
    <origin
      xyz="-0.0765515214055373 0.113257206654859 1.72464898138088"
      rpy="1.31710983659433 0.769136226420715 -0.178410499351034" />
    <parent
      link="tensegrity" />
    <child
      link="detach7" />
    <axis
      xyz="0 0 0" />
  </joint>
  <link
    name="detach8">
    <inertial>
      <origin
        xyz="0.0136167294130276 0.00336313260997945 -0.00458859078875867"
        rpy="0 0 0" />
      <mass
        value="0.00144131652160447" />
      <inertia
        ixx="2.70919111337062E-08"
        ixy="8.31072147902917E-09"
        ixz="-3.60183626082367E-10"
        iyy="7.19839637780109E-08"
        iyz="-9.28387661696574E-11"
        izz="7.65862471238425E-08" />
    </inertial>
    <visual>
      <origin
        xyz="0 0 0"
        rpy="0 0 0" />
      <geometry>
        <mesh
          filename="package://tensegrity/meshes/detach8.STL" />
      </geometry>
      <material
        name="">
        <color
          rgba="1 0.168627450980392 0.168627450980392 1" />
      </material>
    </visual>
    <collision>
      <origin
        xyz="0 0 0"
        rpy="0 0 0" />
      <geometry>
        <mesh
          filename="package://tensegrity/meshes/detach8.STL" />
      </geometry>
    </collision>
  </link>
  <joint
    name="detach8"
    type="fixed">
    <origin
      xyz="-0.16953606313157 0.160516714179241 1.81051902242288"
      rpy="1.31710983659433 0.769136226420716 -0.178410499351032" />
    <parent
      link="tensegrity" />
    <child
      link="detach8" />
    <axis
      xyz="0 0 0" />
  </joint>
  <link
    name="detach9">
    <inertial>
      <origin
        xyz="0.0136167294130275 0.00336313260997939 -0.00458859078875884"
        rpy="0 0 0" />
      <mass
        value="0.00144131652160446" />
      <inertia
        ixx="2.70919111337059E-08"
        ixy="8.3107214790288E-09"
        ixz="-3.60183626082334E-10"
        iyy="7.19839637780106E-08"
        iyz="-9.28387661697029E-11"
        izz="7.65862471238425E-08" />
    </inertial>
    <visual>
      <origin
        xyz="0 0 0"
        rpy="0 0 0" />
      <geometry>
        <mesh
          filename="package://tensegrity/meshes/detach9.STL" />
      </geometry>
      <material
        name="">
        <color
          rgba="1 0.168627450980392 0.168627450980392 1" />
      </material>
    </visual>
    <collision>
      <origin
        xyz="0 0 0"
        rpy="0 0 0" />
      <geometry>
        <mesh
          filename="package://tensegrity/meshes/detach9.STL" />
      </geometry>
    </collision>
  </link>
  <joint
    name="detach9"
    type="fixed">
    <origin
      xyz="0.438575768688868 0.0203654002444033 1.21796640096016"
      rpy="0.253686490200553 -0.769136226420708 2.96318215423877" />
    <parent
      link="tensegrity" />
    <child
      link="detach9" />
    <axis
      xyz="0 0 0" />
  </joint>
  <link
    name="attach1">
    <inertial>
      <origin
        xyz="2.22044604925031E-16 0.0109071136700517 0.00018840146022947"
        rpy="0 0 0" />
      <mass
        value="0.000125397117258045" />
      <inertia
        ixx="5.17034833783075E-09"
        ixy="-1.87844316057696E-23"
        ixz="2.06795153138257E-25"
        iyy="1.14975031600388E-10"
        iyz="-9.61806045495618E-12"
        izz="5.17479932232868E-09" />
    </inertial>
    <visual>
      <origin
        xyz="0 0 0"
        rpy="0 0 0" />
      <geometry>
        <mesh
          filename="package://tensegrity/meshes/attach1.STL" />
      </geometry>
      <material
        name="">
        <color
          rgba="1 0.549019607843137 0 1" />
      </material>
    </visual>
    <collision>
      <origin
        xyz="0 0 0"
        rpy="0 0 0" />
      <geometry>
        <mesh
          filename="package://tensegrity/meshes/attach1.STL" />
      </geometry>
    </collision>
  </link>
  <joint
    name="attach1"
    type="fixed">
    <origin
      xyz="0.330836180337652 0.0959207585222343 1.96919528368496"
      rpy="-0.531711673196898 0.769136226420716 -2.96318215423882" />
    <parent
      link="tensegrity" />
    <child
      link="attach1" />
    <axis
      xyz="0 0 0" />
  </joint>
  <link
    name="attach2">
    <inertial>
      <origin
        xyz="0 0.0109071136700518 0.000188401460229692"
        rpy="0 0 0" />
      <mass
        value="0.000125397117258046" />
      <inertia
        ixx="5.1703483378308E-09"
        ixy="-2.97841566068776E-23"
        ixz="1.75775880167518E-24"
        iyy="1.1497503160039E-10"
        iyz="-9.61806045494377E-12"
        izz="5.17479932232873E-09" />
    </inertial>
    <visual>
      <origin
        xyz="0 0 0"
        rpy="0 0 0" />
      <geometry>
        <mesh
          filename="package://tensegrity/meshes/attach2.STL" />
      </geometry>
      <material
        name="">
        <color
          rgba="1 0.549019607843137 0 1" />
      </material>
    </visual>
    <collision>
      <origin
        xyz="0 0 0"
        rpy="0 0 0" />
      <geometry>
        <mesh
          filename="package://tensegrity/meshes/attach2.STL" />
      </geometry>
    </collision>
  </link>
  <joint
    name="attach2"
    type="fixed">
    <origin
      xyz="-0.386688019933338 0.197454290583016 1.93990580280716"
      rpy="0.531711673196865 0.769136226420715 -0.178410499351044" />
    <parent
      link="tensegrity" />
    <child
      link="attach2" />
    <axis
      xyz="0 0 0" />
  </joint>
  <link
    name="attach3">
    <inertial>
      <origin
        xyz="5.55111512312578E-17 0.0109071136700518 0.000188401460229803"
        rpy="0 0 0" />
      <mass
        value="0.000125397117258043" />
      <inertia
        ixx="5.17034833783068E-09"
        ixy="4.61209737047999E-23"
        ixz="4.39439700418796E-25"
        iyy="1.14975031600385E-10"
        iyz="-9.61806045500821E-12"
        izz="5.1747993223286E-09" />
    </inertial>
    <visual>
      <origin
        xyz="0 0 0"
        rpy="0 0 0" />
      <geometry>
        <mesh
          filename="package://tensegrity/meshes/attach3.STL" />
      </geometry>
      <material
        name="">
        <color
          rgba="1 0.549019607843137 0 1" />
      </material>
    </visual>
    <collision>
      <origin
        xyz="0 0 0"
        rpy="0 0 0" />
      <geometry>
        <mesh
          filename="package://tensegrity/meshes/attach3.STL" />
      </geometry>
    </collision>
  </link>
  <joint
    name="attach3"
    type="fixed">
    <origin
      xyz="-0.659713818386888 -0.128493991794642 1.09364244438357"
      rpy="-2.6098809803929 -0.769136226420708 0.178410499351032" />
    <parent
      link="tensegrity" />
    <child
      link="attach3" />
    <axis
      xyz="0 0 0" />
  </joint>
  <link
    name="attach4">
    <inertial>
      <origin
        xyz="1.66533453693773E-16 0.0109071136700518 0.00018840146022947"
        rpy="0 0 0" />
      <mass
        value="0.000125397117258046" />
      <inertia
        ixx="5.1703483378308E-09"
        ixy="-2.79335015450036E-24"
        ixz="-3.6189151799195E-25"
        iyy="1.1497503160039E-10"
        iyz="-9.6180604549801E-12"
        izz="5.17479932232873E-09" />
    </inertial>
    <visual>
      <origin
        xyz="0 0 0"
        rpy="0 0 0" />
      <geometry>
        <mesh
          filename="package://tensegrity/meshes/attach4.STL" />
      </geometry>
      <material
        name="">
        <color
          rgba="1 0.549019607843137 0 1" />
      </material>
    </visual>
    <collision>
      <origin
        xyz="0 0 0"
        rpy="0 0 0" />
      <geometry>
        <mesh
          filename="package://tensegrity/meshes/attach4.STL" />
      </geometry>
    </collision>
  </link>
  <joint
    name="attach4"
    type="fixed">
    <origin
      xyz="0.559420853294264 -0.0203686209826116 1.0179626488128"
      rpy="1.03908465359801 -0.769136226420713 2.96318215423876" />
    <parent
      link="tensegrity" />
    <child
      link="attach4" />
    <axis
      xyz="0 0 0" />
  </joint>
  <link
    name="attach5">
    <inertial>
      <origin
        xyz="0 0.0109071136700518 0.000188401460229581"
        rpy="0 0 0" />
      <mass
        value="0.000125397117258043" />
      <inertia
        ixx="5.1703483378307E-09"
        ixy="2.2600448416024E-23"
        ixz="-1.91285516652888E-24"
        iyy="1.14975031600385E-10"
        iyz="-9.61806045496496E-12"
        izz="5.17479932232863E-09" />
    </inertial>
    <visual>
      <origin
        xyz="0 0 0"
        rpy="0 0 0" />
      <geometry>
        <mesh
          filename="package://tensegrity/meshes/attach5.STL" />
      </geometry>
      <material
        name="">
        <color
          rgba="1 0.549019607843137 0 1" />
      </material>
    </visual>
    <collision>
      <origin
        xyz="0 0 0"
        rpy="0 0 0" />
      <geometry>
        <mesh
          filename="package://tensegrity/meshes/attach5.STL" />
      </geometry>
    </collision>
  </link>
  <joint
    name="attach5"
    type="fixed">
    <origin
      xyz="0.00132408020216285 -0.619952126384783 1.66259807389183"
      rpy="-2.35619449019234 0.181319774401488 1.57079632679489" />
    <parent
      link="tensegrity" />
    <child
      link="attach5" />
    <axis
      xyz="0 0 0" />
  </joint>
  <link
    name="attach6">
    <inertial>
      <origin
        xyz="-5.55111512312578E-17 0.0109071136700518 0.000188401460229803"
        rpy="0 0 0" />
      <mass
        value="0.000125397117258046" />
      <inertia
        ixx="5.17034833783079E-09"
        ixy="5.47619414904247E-23"
        ixz="1.21492152468726E-24"
        iyy="1.1497503160039E-10"
        iyz="-9.61806045498649E-12"
        izz="5.17479932232871E-09" />
    </inertial>
    <visual>
      <origin
        xyz="0 0 0"
        rpy="0 0 0" />
      <geometry>
        <mesh
          filename="package://tensegrity/meshes/attach6.STL" />
      </geometry>
      <material
        name="">
        <color
          rgba="1 0.549019607843137 0 1" />
      </material>
    </visual>
    <collision>
      <origin
        xyz="0 0 0"
        rpy="0 0 0" />
      <geometry>
        <mesh
          filename="package://tensegrity/meshes/attach6.STL" />
      </geometry>
    </collision>
  </link>
  <joint
    name="attach6"
    type="fixed">
    <origin
      xyz="0.603861978791218 -0.0269604597338994 1.06435296350577"
      rpy="2.60988098039293 -0.769136226420717 2.96318215423874" />
    <parent
      link="tensegrity" />
    <child
      link="attach6" />
    <axis
      xyz="0 0 0" />
  </joint>
  <link
    name="attach7">
    <inertial>
      <origin
        xyz="-0.514790848879533 0.235125274566205 0.394112189841164"
        rpy="0 0 0" />
      <mass
        value="0.000125397117258042" />
      <inertia
        ixx="5.17034833783063E-09"
        ixy="1.62172636500142E-23"
        ixz="-5.06648125188729E-24"
        iyy="1.14975031600381E-10"
        iyz="-9.61806045495912E-12"
        izz="5.17479932232856E-09" />
    </inertial>
    <visual>
      <origin
        xyz="0 0 0"
        rpy="0 0 0" />
      <geometry>
        <mesh
          filename="package://tensegrity/meshes/attach7.STL" />
      </geometry>
      <material
        name="">
        <color
          rgba="1 0.549019607843137 0 1" />
      </material>
    </visual>
    <collision>
      <origin
        xyz="0 0 0"
        rpy="0 0 0" />
      <geometry>
        <mesh
          filename="package://tensegrity/meshes/attach7.STL" />
      </geometry>
    </collision>
  </link>
  <joint
    name="attach7"
    type="fixed">
    <origin
      xyz="-0.386688019933338 0.197454290583016 1.93990580280716"
      rpy="-2.10250799999181 0.769136226420727 -2.96318215423883" />
    <parent
      link="tensegrity" />
    <child
      link="attach7" />
    <axis
      xyz="0 0 0" />
  </joint>
  <link
    name="attach8">
    <inertial>
      <origin
        xyz="-1.11022302462516E-16 0.0109071136700523 0.000188401460229803"
        rpy="0 0 0" />
      <mass
        value="0.000125397117258044" />
      <inertia
        ixx="5.1703483378307E-09"
        ixy="-2.12643578562948E-23"
        ixz="-1.34416849539867E-24"
        iyy="1.14975031600387E-10"
        iyz="-9.6180604549603E-12"
        izz="5.17479932232863E-09" />
    </inertial>
    <visual>
      <origin
        xyz="0 0 0"
        rpy="0 0 0" />
      <geometry>
        <mesh
          filename="package://tensegrity/meshes/attach8.STL" />
      </geometry>
      <material
        name="">
        <color
          rgba="1 0.549019607843137 0 1" />
      </material>
    </visual>
    <collision>
      <origin
        xyz="0 0 0"
        rpy="0 0 0" />
      <geometry>
        <mesh
          filename="package://tensegrity/meshes/attach8.STL" />
      </geometry>
    </collision>
  </link>
  <joint
    name="attach8"
    type="fixed">
    <origin
      xyz="-0.0466759197978372 0.696113447385709 1.42131938536724"
      rpy="-2.35619449019234 -0.181319774401499 -1.5707963267949" />
    <parent
      link="tensegrity" />
    <child
      link="attach8" />
    <axis
      xyz="0 0 0" />
  </joint>
  <link
    name="attach9">
    <inertial>
      <origin
        xyz="0 0.0109071136700518 0.000188401460229581"
        rpy="0 0 0" />
      <mass
        value="0.000125397117258044" />
      <inertia
        ixx="5.17034833783069E-09"
        ixy="2.16052467415462E-23"
        ixz="-1.65436122510606E-24"
        iyy="1.14975031600386E-10"
        iyz="-9.6180604549633E-12"
        izz="5.17479932232862E-09" />
    </inertial>
    <visual>
      <origin
        xyz="0 0 0"
        rpy="0 0 0" />
      <geometry>
        <mesh
          filename="package://tensegrity/meshes/attach9.STL" />
      </geometry>
      <material
        name="">
        <color
          rgba="1 0.549019607843137 0 1" />
      </material>
    </visual>
    <collision>
      <origin
        xyz="0 0 0"
        rpy="0 0 0" />
      <geometry>
        <mesh
          filename="package://tensegrity/meshes/attach9.STL" />
      </geometry>
    </collision>
  </link>
  <joint
    name="attach9"
    type="fixed">
    <origin
      xyz="0.00132408020216294 0.682102245206886 1.34489464621002"
      rpy="0.785398163397449 -0.181319774401489 -1.57079632679489" />
    <parent
      link="tensegrity" />
    <child
      link="attach9" />
    <axis
      xyz="0 0 0" />
  </joint>
  <link
    name="pulley1">
    <inertial>
      <origin
        xyz="-0.00354676805529763 -0.001495694973495 -0.0237500000000001"
        rpy="0 0 0" />
      <mass
        value="0.00115149136839394" />
      <inertia
        ixx="2.47202230080769E-08"
        ixy="-1.65436122510606E-24"
        ixz="-1.04381600812693E-24"
        iyy="2.47202230080769E-08"
        iyz="3.27550542609021E-25"
        izz="2.72844075510586E-08" />
    </inertial>
    <visual>
      <origin
        xyz="0 0 0"
        rpy="0 0 0" />
      <geometry>
        <mesh
          filename="package://tensegrity/meshes/pulley1.STL" />
      </geometry>
      <material
        name="">
        <color
          rgba="1 1 0 1" />
      </material>
    </visual>
    <collision>
      <origin
        xyz="0 0 0"
        rpy="0 0 0" />
      <geometry>
        <mesh
          filename="package://tensegrity/meshes/pulley1.STL" />
      </geometry>
    </collision>
  </link>
  <joint
    name="pulley1"
    type="continuous">
    <origin
      xyz="-0.0466759197978372 0.696113447385709 1.42131938536724"
      rpy="1.5707963267949 -1.35303842246507 -1.5707963267949" />
    <parent
      link="tensegrity" />
    <child
      link="pulley1" />
    <axis
      xyz="0 0 1" />
  </joint>
  <link
    name="pulley2">
    <inertial>
      <origin
        xyz="-1.38777878078145E-16 2.22044604925031E-16 0.00132017230202797"
        rpy="0 0 0" />
      <mass
        value="0.00115149136839393" />
      <inertia
        ixx="2.47202230080765E-08"
        ixy="4.13590306276514E-24"
        ixz="9.40917946779069E-23"
        iyy="2.47202230080765E-08"
        iyz="-7.11375326795604E-23"
        izz="2.72844075510583E-08" />
    </inertial>
    <visual>
      <origin
        xyz="0 0 0"
        rpy="0 0 0" />
      <geometry>
        <mesh
          filename="package://tensegrity/meshes/pulley2.STL" />
      </geometry>
      <material
        name="">
        <color
          rgba="1 1 0 1" />
      </material>
    </visual>
    <collision>
      <origin
        xyz="0 0 0"
        rpy="0 0 0" />
      <geometry>
        <mesh
          filename="package://tensegrity/meshes/pulley2.STL" />
      </geometry>
    </collision>
  </link>
  <joint
    name="pulley2"
    type="continuous">
    <origin
      xyz="-0.631486529546608 -0.0755513717494224 1.055238553721"
      rpy="0.631420863095884 0.532284485238217 -2.35588130681373" />
    <parent
      link="tensegrity" />
    <child
      link="pulley2" />
    <axis
      xyz="0 0 1" />
  </joint>
  <link
    name="pulley3">
    <inertial>
      <origin
        xyz="5.55111512312578E-17 2.22044604925031E-16 -0.00444107766729429"
        rpy="0 0 0" />
      <mass
        value="0.00115149136839394" />
      <inertia
        ixx="2.47202230080766E-08"
        ixy="1.65436122510606E-24"
        ixz="-4.09454403213749E-23"
        iyy="2.47202230080766E-08"
        iyz="-2.27474668452083E-23"
        izz="2.72844075510585E-08" />
    </inertial>
    <visual>
      <origin
        xyz="0 0 0"
        rpy="0 0 0" />
      <geometry>
        <mesh
          filename="package://tensegrity/meshes/pulley3.STL" />
      </geometry>
      <material
        name="">
        <color
          rgba="1 1 0 1" />
      </material>
    </visual>
    <collision>
      <origin
        xyz="0 0 0"
        rpy="0 0 0" />
      <geometry>
        <mesh
          filename="package://tensegrity/meshes/pulley3.STL" />
      </geometry>
    </collision>
  </link>
  <joint
    name="pulley3"
    type="continuous">
    <origin
      xyz="-0.0576759197978372 -0.627713495578133 1.62026333283719"
      rpy="2.98449472353879 -0.0909133937987542 -0.520440071048007" />
    <parent
      link="tensegrity" />
    <child
      link="pulley3" />
    <axis
      xyz="0 0 1" />
  </joint>
  <link
    name="pulley4">
    <inertial>
      <origin
        xyz="0.00295779913067254 0.00258610371821444 -0.0320281745930517"
        rpy="0 0 0" />
      <mass
        value="0.00115149136839396" />
      <inertia
        ixx="2.47202230080774E-08"
        ixy="-2.48154183765908E-24"
        ixz="9.92616735063633E-24"
        iyy="2.47202230080774E-08"
        iyz="2.64697796016969E-23"
        izz="2.72844075510591E-08" />
    </inertial>
    <visual>
      <origin
        xyz="0 0 0"
        rpy="0 0 0" />
      <geometry>
        <mesh
          filename="package://tensegrity/meshes/pulley4.STL" />
      </geometry>
      <material
        name="">
        <color
          rgba="1 1 0 1" />
      </material>
    </visual>
    <collision>
      <origin
        xyz="0 0 0"
        rpy="0 0 0" />
      <geometry>
        <mesh
          filename="package://tensegrity/meshes/pulley4.STL" />
      </geometry>
    </collision>
  </link>
  <joint
    name="pulley4"
    type="continuous">
    <origin
      xyz="-0.654713818386888 -0.136350779806313 1.08999952218571"
      rpy="0.745639043009377 0.327890658213947 -2.08475010947139" />
    <parent
      link="tensegrity" />
    <child
      link="pulley4" />
    <axis
      xyz="0 0 1" />
  </joint>
  <link
    name="pulley5">
    <inertial>
      <origin
        xyz="0.0036625051002005 -0.00118436627901386 0.0237500000000027"
        rpy="0 0 0" />
      <mass
        value="0.00115149136839394" />
      <inertia
        ixx="2.47202230080769E-08"
        ixy="6.72084247699335E-25"
        ixz="4.65289094561078E-23"
        iyy="2.47202230080769E-08"
        iyz="-3.97046694025453E-23"
        izz="2.72844075510587E-08" />
    </inertial>
    <visual>
      <origin
        xyz="0 0 0"
        rpy="0 0 0" />
      <geometry>
        <mesh
          filename="package://tensegrity/meshes/pulley5.STL" />
      </geometry>
      <material
        name="">
        <color
          rgba="1 1 0 1" />
      </material>
    </visual>
    <collision>
      <origin
        xyz="0 0 0"
        rpy="0 0 0" />
      <geometry>
        <mesh
          filename="package://tensegrity/meshes/pulley5.STL" />
      </geometry>
    </collision>
  </link>
  <joint
    name="pulley5"
    type="continuous">
    <origin
      xyz="0.286395054840697 0.089328919770948 2.01558559837794"
      rpy="1.36772787967172 0.464271853741143 -0.0919392370595982" />
    <parent
      link="tensegrity" />
    <child
      link="pulley5" />
    <axis
      xyz="0 0 -1" />
  </joint>
  <link
    name="pulley6">
    <inertial>
      <origin
        xyz="0.00759375599200873 0.0695868871981916 -0.0039410776672939"
        rpy="0 0 0" />
      <mass
        value="0.00115149136839394" />
      <inertia
        ixx="2.47202230080766E-08"
        ixy="-4.13590306276514E-25"
        ixz="5.50075107347763E-23"
        iyy="2.47202230080766E-08"
        iyz="-6.77254126527791E-24"
        izz="2.72844075510585E-08" />
    </inertial>
    <visual>
      <origin
        xyz="0 0 0"
        rpy="0 0 0" />
      <geometry>
        <mesh
          filename="package://tensegrity/meshes/pulley6.STL" />
      </geometry>
      <material
        name="">
        <color
          rgba="1 1 0 1" />
      </material>
    </visual>
    <collision>
      <origin
        xyz="0 0 0"
        rpy="0 0 0" />
      <geometry>
        <mesh
          filename="package://tensegrity/meshes/pulley6.STL" />
      </geometry>
    </collision>
  </link>
  <joint
    name="pulley6"
    type="continuous">
    <origin
      xyz="-0.0576759197978372 -0.627713495578133 1.62026333283719"
      rpy="3.12170686669581 0.180237919378081 1.4603031742211" />
    <parent
      link="tensegrity" />
    <child
      link="pulley6" />
    <axis
      xyz="0 0 1" />
  </joint>
  <link
    name="pulley7">
    <inertial>
      <origin
        xyz="-0.0192366243701161 0.447101169545541 0.476191606474618"
        rpy="0 0 0" />
      <mass
        value="0.00115149136839396" />
      <inertia
        ixx="2.47202230080772E-08"
        ixy="-4.13590306276514E-25"
        ixz="-1.96455395481344E-23"
        iyy="2.47202230080772E-08"
        iyz="-5.05614149423038E-23"
        izz="2.7284407551059E-08" />
    </inertial>
    <visual>
      <origin
        xyz="0 0 0"
        rpy="0 0 0" />
      <geometry>
        <mesh
          filename="package://tensegrity/meshes/pulley7.STL" />
      </geometry>
      <material
        name="">
        <color
          rgba="1 1 0 1" />
      </material>
    </visual>
    <collision>
      <origin
        xyz="0 0 0"
        rpy="0 0 0" />
      <geometry>
        <mesh
          filename="package://tensegrity/meshes/pulley7.STL" />
      </geometry>
    </collision>
  </link>
  <joint
    name="pulley7"
    type="continuous">
    <origin
      xyz="0.289116880247657 0.0736709705934651 2.01568903323008"
      rpy="2.37738677488523 -0.271358663823416 -1.66506917334562" />
    <parent
      link="tensegrity" />
    <child
      link="pulley7" />
    <axis
      xyz="0 0 1" />
  </joint>
  <link
    name="pulley8">
    <inertial>
      <origin
        xyz="0.0109929639978546 0.000393373286307952 0.0390992424049179"
        rpy="0 0 0" />
      <mass
        value="0.00115149136839396" />
      <inertia
        ixx="2.47202230080772E-08"
        ixy="0"
        ixz="4.96308367531817E-24"
        iyy="2.47202230080772E-08"
        iyz="4.85968609874904E-23"
        izz="2.7284407551059E-08" />
    </inertial>
    <visual>
      <origin
        xyz="0 0 0"
        rpy="0 0 0" />
      <geometry>
        <mesh
          filename="package://tensegrity/meshes/pulley8.STL" />
      </geometry>
      <material
        name="">
        <color
          rgba="1 1 0 1" />
      </material>
    </visual>
    <collision>
      <origin
        xyz="0 0 0"
        rpy="0 0 0" />
      <geometry>
        <mesh
          filename="package://tensegrity/meshes/pulley8.STL" />
      </geometry>
    </collision>
  </link>
  <joint
    name="pulley8"
    type="continuous">
    <origin
      xyz="-0.386688019933338 0.197454290583016 1.93990580280716"
      rpy="0.780417755714486 0.206550528203247 1.54495729002601" />
    <parent
      link="tensegrity" />
    <child
      link="pulley8" />
    <axis
      xyz="0 0 -1" />
  </joint>
  <link
    name="pulley9">
    <inertial>
      <origin
        xyz="1.11022302462516E-16 2.22044604925031E-16 0.00741057511421689"
        rpy="0 0 0" />
      <mass
        value="0.00115149136839394" />
      <inertia
        ixx="2.47202230080768E-08"
        ixy="-1.28090127235951E-25"
        ixz="-8.53487155171088E-24"
        iyy="2.47202230080768E-08"
        iyz="-1.14978105144871E-22"
        izz="2.72844075510586E-08" />
    </inertial>
    <visual>
      <origin
        xyz="0 0 0"
        rpy="0 0 0" />
      <geometry>
        <mesh
          filename="package://tensegrity/meshes/pulley9.STL" />
      </geometry>
      <material
        name="">
        <color
          rgba="1 1 0 1" />
      </material>
    </visual>
    <collision>
      <origin
        xyz="0 0 0"
        rpy="0 0 0" />
      <geometry>
        <mesh
          filename="package://tensegrity/meshes/pulley9.STL" />
      </geometry>
    </collision>
  </link>
  <joint
    name="pulley9"
    type="continuous">
    <origin
      xyz="0.611640153384268 0.0201895234082593 1.06361661076598"
      rpy="1.3894765523934 0 0" />
    <parent
      link="tensegrity" />
    <child
      link="pulley9" />
    <axis
      xyz="0 0 -1" />
  </joint>
  <link
    name="tendon1">
    <inertial>
      <origin
        xyz="0.0280452611142127 0.455678964123524 -0.00616505369708431"
        rpy="0 0 0" />
      <mass
        value="0.0112203866578552" />
      <inertia
        ixx="0.000745468045263643"
        ixy="-2.02405388345499E-18"
        ixz="-2.03287907341032E-20"
        iyy="2.24407733156494E-08"
        iyz="-1.82069566576189E-18"
        izz="0.000745468045263642" />
    </inertial>
    <visual>
      <origin
        xyz="0 0 0"
        rpy="0 0 0" />
      <geometry>
        <mesh
          filename="package://tensegrity/meshes/tendon1.STL" />
      </geometry>
      <material
        name="">
        <color
          rgba="0.792156862745098 0.819607843137255 0.933333333333333 1" />
      </material>
    </visual>
    <collision>
      <origin
        xyz="0 0 0"
        rpy="0 0 0" />
      <geometry>
        <mesh
          filename="package://tensegrity/meshes/tendon1.STL" />
      </geometry>
    </collision>
  </link>
  <joint
    name="tendon1"
    type="continuous">
    <origin
      xyz="-0.0466759197978372 0.696113447385709 1.42131938536724"
      rpy="2.42029878837546 0.411085599759094 0.18803458251" />
    <parent
      link="tensegrity" />
    <child
      link="tendon1" />
    <axis
      xyz="0 -1 0" />
  </joint>
  <link
    name="tendon2">
    <inertial>
      <origin
        xyz="5.55111512312578E-16 0.402744460498145 -2.22044604925031E-16"
        rpy="0 0 0" />
      <mass
        value="0.0122147635645694" />
      <inertia
        ixx="0.000961744555970351"
        ixy="1.71671492686092E-18"
        ixz="-3.72694496791892E-20"
        iyy="2.44295271292102E-08"
        iyz="-4.17659207709662E-19"
        izz="0.000961744555970352" />
    </inertial>
    <visual>
      <origin
        xyz="0 0 0"
        rpy="0 0 0" />
      <geometry>
        <mesh
          filename="package://tensegrity/meshes/tendon2.STL" />
      </geometry>
      <material
        name="">
        <color
          rgba="0.792156862745098 0.819607843137255 0.933333333333333 1" />
      </material>
    </visual>
    <collision>
      <origin
        xyz="0 0 0"
        rpy="0 0 0" />
      <geometry>
        <mesh
          filename="package://tensegrity/meshes/tendon2.STL" />
      </geometry>
    </collision>
  </link>
  <joint
    name="tendon2"
    type="continuous">
    <origin
      xyz="-0.608609359052292 -0.0491036055084579 1.12579281338414"
      rpy="1.26117971092963 0.261335644435745 -0.0410112084771942" />
    <parent
      link="tensegrity" />
    <child
      link="tendon2" />
    <axis
      xyz="0 -1 0" />
  </joint>
  <link
    name="tendon3">
    <inertial>
      <origin
        xyz="-0.00215504715329384 0.475623558100835 0.00269565824071605"
        rpy="0 0 0" />
      <mass
        value="0.0118593866035953" />
      <inertia
        ixx="0.000880220659918278"
        ixy="-1.72088846664155E-18"
        ixz="-5.42101086242752E-20"
        iyy="2.37187732071377E-08"
        iyz="3.68794340203705E-19"
        izz="0.000880220659918277" />
    </inertial>
    <visual>
      <origin
        xyz="0 0 0"
        rpy="0 0 0" />
      <geometry>
        <mesh
          filename="package://tensegrity/meshes/tendon3.STL" />
      </geometry>
      <material
        name="">
        <color
          rgba="0.792156862745098 0.819607843137255 0.933333333333333 1" />
      </material>
    </visual>
    <collision>
      <origin
        xyz="0 0 0"
        rpy="0 0 0" />
      <geometry>
        <mesh
          filename="package://tensegrity/meshes/tendon3.STL" />
      </geometry>
    </collision>
  </link>
  <joint
    name="tendon3"
    type="continuous">
    <origin
      xyz="-0.659713818386888 -0.128493991794642 1.09364244438357"
      rpy="2.31796632388059 0.687403267030743 0.278774820132193" />
    <parent
      link="tensegrity" />
    <child
      link="tendon3" />
    <axis
      xyz="0 -1 0" />
  </joint>
  <link
    name="tendon4">
    <inertial>
      <origin
        xyz="6.66133814775094E-16 0.0925594603944367 -6.93889390390723E-17"
        rpy="0 0 0" />
      <mass
        value="0.0151436075636581" />
      <inertia
        ixx="0.00183269693892127"
        ixy="1.58732228964363E-17"
        ixz="2.71050543121376E-20"
        iyy="3.0287215127313E-08"
        iyz="-1.1189518232237E-18"
        izz="0.00183269693892127" />
    </inertial>
    <visual>
      <origin
        xyz="0 0 0"
        rpy="0 0 0" />
      <geometry>
        <mesh
          filename="package://tensegrity/meshes/tendon4.STL" />
      </geometry>
      <material
        name="">
        <color
          rgba="0.792156862745098 0.819607843137255 0.933333333333333 1" />
      </material>
    </visual>
    <collision>
      <origin
        xyz="0 0 0"
        rpy="0 0 0" />
      <geometry>
        <mesh
          filename="package://tensegrity/meshes/tendon4.STL" />
      </geometry>
    </collision>
  </link>
  <joint
    name="tendon4"
    type="continuous">
    <origin
      xyz="0.0523061208957168 -0.0765710892010435 1.04170605862146"
      rpy="2.74376898576192 -1.46092772171524 -1.07377843875898" />
    <parent
      link="tensegrity" />
    <child
      link="tendon4" />
    <axis
      xyz="0 1 0" />
  </joint>
  <link
    name="tendon5">
    <inertial>
      <origin
        xyz="-9.71445146547012E-17 -4.44089209850063E-16 -0.154547245545221"
        rpy="0 0 0" />
      <mass
        value="0.010344259298622" />
      <inertia
        ixx="0.000584123813931166"
        ixy="5.42101086242752E-20"
        ixz="5.07136988930748E-19"
        iyy="0.000584123813931166"
        iyz="2.02079065593847E-18"
        izz="2.06885185972775E-08" />
    </inertial>
    <visual>
      <origin
        xyz="0 0 0"
        rpy="0 0 0" />
      <geometry>
        <mesh
          filename="package://tensegrity/meshes/tendon5.STL" />
      </geometry>
      <material
        name="">
        <color
          rgba="0.792156862745098 0.819607843137255 0.933333333333333 1" />
      </material>
    </visual>
    <collision>
      <origin
        xyz="0 0 0"
        rpy="0 0 0" />
      <geometry>
        <mesh
          filename="package://tensegrity/meshes/tendon5.STL" />
      </geometry>
    </collision>
  </link>
  <joint
    name="tendon5"
    type="continuous">
    <origin
      xyz="0.100914183112479 -0.409510270989431 1.76840273399034"
      rpy="2.03791065757841 0.0816434120527184 -0.340060952463484" />
    <parent
      link="tensegrity" />
    <child
      link="tendon5" />
    <axis
      xyz="0 0 1" />
  </joint>
  <link
    name="tendon6">
    <inertial>
      <origin
        xyz="-1.11022302462516E-15 0.16127873743604 8.32667268468867E-16"
        rpy="0 0 0" />
      <mass
        value="0.0128653245712748" />
      <inertia
        ixx="0.00112374103417609"
        ixy="-6.18164293354428E-18"
        ixz="-1.0842021724855E-19"
        iyy="2.57306491423624E-08"
        iyz="6.54946719768461E-18"
        izz="0.00112374103417609" />
    </inertial>
    <visual>
      <origin
        xyz="0 0 0"
        rpy="0 0 0" />
      <geometry>
        <mesh
          filename="package://tensegrity/meshes/tendon6.STL" />
      </geometry>
      <material
        name="">
        <color
          rgba="0.792156862745098 0.819607843137255 0.933333333333333 1" />
      </material>
    </visual>
    <collision>
      <origin
        xyz="0 0 0"
        rpy="0 0 0" />
      <geometry>
        <mesh
          filename="package://tensegrity/meshes/tendon6.STL" />
      </geometry>
    </collision>
  </link>
  <joint
    name="tendon6"
    type="continuous">
    <origin
      xyz="0.410004431861938 -0.225457324111191 1.26383576024815"
      rpy="2.40337970476027 -0.626481292974809 -0.284482754458899" />
    <parent
      link="tensegrity" />
    <child
      link="tendon6" />
    <axis
      xyz="0 -1 0" />
  </joint>
  <link
    name="tendon7">
    <inertial>
      <origin
        xyz="0.0111145592446351 -0.32496463494794 -0.0122334158653825"
        rpy="0 0 0" />
      <mass
        value="0.00829493557883235" />
      <inertia
        ixx="0.000301196581908505"
        ixy="-3.05212369266375E-18"
        ixz="-3.3881317890172E-21"
        iyy="1.65898711576636E-08"
        iyz="-1.97463832045623E-19"
        izz="0.000301196581908505" />
    </inertial>
    <visual>
      <origin
        xyz="0 0 0"
        rpy="0 0 0" />
      <geometry>
        <mesh
          filename="package://tensegrity/meshes/tendon7.STL" />
      </geometry>
      <material
        name="">
        <color
          rgba="0.792156862745098 0.819607843137255 0.933333333333333 1" />
      </material>
    </visual>
    <collision>
      <origin
        xyz="0 0 0"
        rpy="0 0 0" />
      <geometry>
        <mesh
          filename="package://tensegrity/meshes/tendon7.STL" />
      </geometry>
    </collision>
  </link>
  <joint
    name="tendon7"
    type="continuous">
    <origin
      xyz="0.286395054840697 0.089328919770948 2.01558559837794"
      rpy="2.49743103048459 1.49647330665931 0.868493247146079" />
    <parent
      link="tensegrity" />
    <child
      link="tendon7" />
    <axis
      xyz="0 -1 0" />
  </joint>
  <link
    name="tendon8">
    <inertial>
      <origin
        xyz="1.11022302462516E-15 0.287575538502798 -4.44089209850063E-16"
        rpy="0 0 0" />
      <mass
        value="0.00996651419795441" />
      <inertia
        ixx="0.0005224409136418"
        ixy="1.97207188920821E-18"
        ixz="1.01643953670516E-20"
        iyy="1.99330283959869E-08"
        iyz="-1.34105498757302E-18"
        izz="0.0005224409136418" />
    </inertial>
    <visual>
      <origin
        xyz="0 0 0"
        rpy="0 0 0" />
      <geometry>
        <mesh
          filename="package://tensegrity/meshes/tendon8.STL" />
      </geometry>
      <material
        name="">
        <color
          rgba="0.792156862745098 0.819607843137255 0.933333333333333 1" />
      </material>
    </visual>
    <collision>
      <origin
        xyz="0 0 0"
        rpy="0 0 0" />
      <geometry>
        <mesh
          filename="package://tensegrity/meshes/tendon8.STL" />
      </geometry>
    </collision>
  </link>
  <joint
    name="tendon8"
    type="continuous">
    <origin
      xyz="-0.101528663990072 0.629633422043848 1.48824784214199"
      rpy="2.27799917995113 -0.382849686510957 -0.142824130650291" />
    <parent
      link="tensegrity" />
    <child
      link="tendon8" />
    <axis
      xyz="0 -1 0" />
  </joint>
  <link
    name="tendon9">
    <inertial>
      <origin
        xyz="1.33226762955019E-15 0.399512964030009 8.88178419700125E-16"
        rpy="0 0 0" />
      <mass
        value="0.0119694680101771" />
      <inertia
        ixx="0.000904959857918698"
        ixy="2.91783742456956E-18"
        ixz="9.48676900924816E-20"
        iyy="2.39389360204049E-08"
        iyz="1.9213900160892E-18"
        izz="0.000904959857918698" />
    </inertial>
    <visual>
      <origin
        xyz="0 0 0"
        rpy="0 0 0" />
      <geometry>
        <mesh
          filename="package://tensegrity/meshes/tendon9.STL" />
      </geometry>
      <material
        name="">
        <color
          rgba="0.792156862745098 0.819607843137255 0.933333333333333 1" />
      </material>
    </visual>
    <collision>
      <origin
        xyz="0 0 0"
        rpy="0 0 0" />
      <geometry>
        <mesh
          filename="package://tensegrity/meshes/tendon9.STL" />
      </geometry>
    </collision>
  </link>
  <joint
    name="tendon9"
    type="continuous">
    <origin
      xyz="0.566770118853501 0.0612514071392795 1.08858398583577"
      rpy="0.391601755363025 -0.694514754049021 0.475091260901225" />
    <parent
      link="tensegrity" />
    <child
      link="tendon9" />
    <axis
      xyz="0 1 0" />
  </joint>
</robot>