<robot
  name="tensegrity">
  <link
    name="tensegrity">
    <inertial>
      <origin
        xyz="-1.70342435387228E-05 0.0025434679453309 0.912664896869721"
        rpy="0 0 0" />
      <mass
        value="3.00549585119547" />
      <inertia
        ixx="1.53216654931884"
        ixy="-0.00583460267481173"
        ixz="0.000937123075737038"
        iyy="1.54520203393677"
        iyz="0.00447932044270713"
        izz="0.15023504147663" />
    </inertial>
    <visual>
      <origin
        xyz="0 0 0"
        rpy="0 0 0" />
      <geometry>
        <mesh
          filename="package://tensegrity/meshes/tensegrity.STL" />
      </geometry>
      <material
        name="">
        <color
          rgba="0.792156862745098 0.819607843137255 0.933333333333333 1" />
      </material>
    </visual>
    <collision>
      <origin
        xyz="0 0 0"
        rpy="0 0 0" />
      <geometry>
        <mesh
          filename="package://tensegrity/meshes/tensegrity.STL" />
      </geometry>
    </collision>
  </link>
  <link
    name="tightener1">
    <inertial>
      <origin
        xyz="0.0352544610406252 0.00483657039288032 0.00519743752472746"
        rpy="0 0 0" />
      <mass
        value="0.0085646299641912" />
      <inertia
        ixx="9.48346301710469E-07"
        ixy="4.66685161768164E-07"
        ixz="5.01471138407425E-07"
        iyy="3.09043873265828E-06"
        iyz="1.90238552895543E-07"
        izz="2.84368398126268E-06" />
    </inertial>
    <visual>
      <origin
        xyz="0 0 0"
        rpy="0 0 0" />
      <geometry>
        <mesh
          filename="package://tensegrity/meshes/tightener1.STL" />
      </geometry>
      <material
        name="">
        <color
          rgba="0.792156862745098 0.819607843137255 0.933333333333333 1" />
      </material>
    </visual>
    <collision>
      <origin
        xyz="0 0 0"
        rpy="0 0 0" />
      <geometry>
        <mesh
          filename="package://tensegrity/meshes/tightener1.STL" />
      </geometry>
    </collision>
  </link>
  <joint
    name="tightener1"
    type="fixed">
    <origin
      xyz="0.0440793418117183 0.335790163934433 1.48974180327869"
      rpy="0.181319774401501 0 3.14159265358979" />
    <parent
      link="tensegrity" />
    <child
      link="tightener1" />
    <axis
      xyz="0 0 0" />
  </joint>
  <link
    name="tightener2">
    <inertial>
      <origin
        xyz="0.0352544394300565 0.00483661082832576 0.0051974404779622"
        rpy="0 0 0" />
      <mass
        value="0.00856464520084458" />
      <inertia
        ixx="9.48345554667794E-07"
        ixy="4.66676495816721E-07"
        ixz="5.01469301430558E-07"
        iyy="3.09044286567929E-06"
        iyz="1.90238499470876E-07"
        izz="2.84368695035451E-06" />
    </inertial>
    <visual>
      <origin
        xyz="0 0 0"
        rpy="0 0 0" />
      <geometry>
        <mesh
          filename="package://tensegrity/meshes/tightener2.STL" />
      </geometry>
      <material
        name="">
        <color
          rgba="0.792156862745098 0.819607843137255 0.933333333333333 1" />
      </material>
    </visual>
    <collision>
      <origin
        xyz="0 0 0"
        rpy="0 0 0" />
      <geometry>
        <mesh
          filename="package://tensegrity/meshes/tightener2.STL" />
      </geometry>
    </collision>
  </link>
  <joint
    name="tightener2"
    type="fixed">
    <origin
      xyz="-0.390243560110425 0.035800670929021 1.36207638688557"
      rpy="-1.82448281699546 0.769136226420719 -0.178410499351027" />
    <parent
      link="tensegrity" />
    <child
      link="tightener2" />
    <axis
      xyz="0 0 0" />
  </joint>
  <link
    name="tightener3">
    <inertial>
      <origin
        xyz="0.0352544375924035 0.00483656711376768 0.00519743422688456"
        rpy="0 0 0" />
      <mass
        value="0.00856463183459577" />
      <inertia
        ixx="9.48348547824701E-07"
        ixy="4.66688007253595E-07"
        ixz="5.01471990198089E-07"
        iyy="3.09044823930521E-06"
        iyz="1.90239037244562E-07"
        izz="2.84369551495917E-06" />
    </inertial>
    <visual>
      <origin
        xyz="0 0 0"
        rpy="0 0 0" />
      <geometry>
        <mesh
          filename="package://tensegrity/meshes/tightener3.STL" />
      </geometry>
      <material
        name="">
        <color
          rgba="0.792156862745098 0.819607843137255 0.933333333333333 1" />
      </material>
    </visual>
    <collision>
      <origin
        xyz="0 0 0"
        rpy="0 0 0" />
      <geometry>
        <mesh
          filename="package://tensegrity/meshes/tightener3.STL" />
      </geometry>
    </collision>
  </link>
  <joint
    name="tightener3"
    type="fixed">
    <origin
      xyz="-0.0011999999999311 -0.296182413771663 1.64716410669998"
      rpy="1.57079632679489 1.3894765523934 -1.5707963267949" />
    <parent
      link="tensegrity" />
    <child
      link="tightener3" />
    <axis
      xyz="0 0 0" />
  </joint>
  <link
    name="tightener4">
    <inertial>
      <origin
        xyz="0.035254437813512 0.00483654893735441 0.00519743300736408"
        rpy="0 0 0" />
      <mass
        value="0.0085646328058922" />
      <inertia
        ixx="9.48350705657278E-07"
        ixy="4.66692396032724E-07"
        ixz="5.01472185592001E-07"
        iyy="3.09044783790211E-06"
        iyz="1.90239467213094E-07"
        izz="2.84369724363878E-06" />
    </inertial>
    <visual>
      <origin
        xyz="0 0 0"
        rpy="0 0 0" />
      <geometry>
        <mesh
          filename="package://tensegrity/meshes/tightener4.STL" />
      </geometry>
      <material
        name="">
        <color
          rgba="0.792156862745098 0.819607843137255 0.933333333333333 1" />
      </material>
    </visual>
    <collision>
      <origin
        xyz="0 0 0"
        rpy="0 0 0" />
      <geometry>
        <mesh
          filename="package://tensegrity/meshes/tightener4.STL" />
      </geometry>
    </collision>
  </link>
  <joint
    name="tightener4"
    type="fixed">
    <origin
      xyz="-0.297259018384395 0.0482405063222401 1.45433003448494"
      rpy="1.31710983659433 0.769136226420719 -0.178410499351027" />
    <parent
      link="tensegrity" />
    <child
      link="tightener4" />
    <axis
      xyz="0 0 0" />
  </joint>
  <link
    name="tightener5">
    <inertial>
      <origin
        xyz="0.0352543983632763 0.0048366923228893 0.00519746072280203"
        rpy="0 0 0" />
      <mass
        value="0.00856464027785653" />
      <inertia
        ixx="9.48335413159074E-07"
        ixy="4.66656916939371E-07"
        ixz="5.01466109552565E-07"
        iyy="3.09045336216777E-06"
        iyz="1.90235224144576E-07"
        izz="2.84368908467771E-06" />
    </inertial>
    <visual>
      <origin
        xyz="0 0 0"
        rpy="0 0 0" />
      <geometry>
        <mesh
          filename="package://tensegrity/meshes/tightener5.STL" />
      </geometry>
      <material
        name="">
        <color
          rgba="0.792156862745098 0.819607843137255 0.933333333333333 1" />
      </material>
    </visual>
    <collision>
      <origin
        xyz="0 0 0"
        rpy="0 0 0" />
      <geometry>
        <mesh
          filename="package://tensegrity/meshes/tightener5.STL" />
      </geometry>
    </collision>
  </link>
  <joint
    name="tightener5"
    type="fixed">
    <origin
      xyz="0.0982819074662917 0.0689332335343484 1.79389398750648"
      rpy="-0.785398163397444 0.181319774401482 1.57079632679491" />
    <parent
      link="tensegrity" />
    <child
      link="tightener5" />
    <axis
      xyz="0 0 0" />
  </joint>
  <link
    name="tightener6">
    <inertial>
      <origin
        xyz="0.0352544664172667 0.00483656939394717 0.00519743601282992"
        rpy="0 0 0" />
      <mass
        value="0.00856463401560592" />
      <inertia
        ixx="9.48346993966001E-07"
        ixy="4.66685035810932E-07"
        ixz="5.0147110726058E-07"
        iyy="3.09043623385776E-06"
        iyz="1.90238686898346E-07"
        izz="2.84368201569931E-06" />
    </inertial>
    <visual>
      <origin
        xyz="0 0 0"
        rpy="0 0 0" />
      <geometry>
        <mesh
          filename="package://tensegrity/meshes/tightener6.STL" />
      </geometry>
      <material
        name="">
        <color
          rgba="0.792156862745098 0.819607843137255 0.933333333333333 1" />
      </material>
    </visual>
    <collision>
      <origin
        xyz="0 0 0"
        rpy="0 0 0" />
      <geometry>
        <mesh
          filename="package://tensegrity/meshes/tightener6.STL" />
      </geometry>
    </collision>
  </link>
  <joint
    name="tightener6"
    type="fixed">
    <origin
      xyz="0.00320000000006892 -0.166838151476581 1.62345099194588"
      rpy="-1.5707963267949 1.3894765523934 -1.5707963267949" />
    <parent
      link="tensegrity" />
    <child
      link="tightener6" />
    <axis
      xyz="0 0 0" />
  </joint>
  <link
    name="tightener7">
    <inertial>
      <origin
        xyz="0.035254465843934 0.00483656282940381 0.00519743225970332"
        rpy="0 0 0" />
      <mass
        value="0.00856463670998783" />
      <inertia
        ixx="9.48347440075924E-07"
        ixy="4.6668640588543E-07"
        ixz="5.01471905064648E-07"
        iyy="3.09043582663786E-06"
        iyz="1.90238697252738E-07"
        izz="2.84368197914403E-06" />
    </inertial>
    <visual>
      <origin
        xyz="0 0 0"
        rpy="0 0 0" />
      <geometry>
        <mesh
          filename="package://tensegrity/meshes/tightener7.STL" />
      </geometry>
      <material
        name="">
        <color
          rgba="0.792156862745098 0.819607843137255 0.933333333333333 1" />
      </material>
    </visual>
    <collision>
      <origin
        xyz="0 0 0"
        rpy="0 0 0" />
      <geometry>
        <mesh
          filename="package://tensegrity/meshes/tightener7.STL" />
      </geometry>
    </collision>
  </link>
  <joint
    name="tightener7"
    type="fixed">
    <origin
      xyz="0.0366901695172931 -0.0231488885293931 1.73038788074873"
      rpy="-1.31710983659433 0.769136226420714 -2.96318215423875" />
    <parent
      link="tensegrity" />
    <child
      link="tightener7" />
    <axis
      xyz="0 0 0" />
  </joint>
  <link
    name="tightener8">
    <inertial>
      <origin
        xyz="0.0352544123736394 0.00483660191451096 0.00519743311534426"
        rpy="0 0 0" />
      <mass
        value="0.00856465792468876" />
      <inertia
        ixx="9.48345449564237E-07"
        ixy="4.66677519510072E-07"
        ixz="5.01470596503675E-07"
        iyy="3.09044836028267E-06"
        iyz="1.90238351816119E-07"
        izz="2.84369196118563E-06" />
    </inertial>
    <visual>
      <origin
        xyz="0 0 0"
        rpy="0 0 0" />
      <geometry>
        <mesh
          filename="package://tensegrity/meshes/tightener8.STL" />
      </geometry>
      <material
        name="">
        <color
          rgba="0.792156862745098 0.819607843137255 0.933333333333333 1" />
      </material>
    </visual>
    <collision>
      <origin
        xyz="0 0 0"
        rpy="0 0 0" />
      <geometry>
        <mesh
          filename="package://tensegrity/meshes/tightener8.STL" />
      </geometry>
    </collision>
  </link>
  <joint
    name="tightener8"
    type="fixed">
    <origin
      xyz="-0.0562943722087432 -0.00205331543125625 1.8210546431022"
      rpy="1.82448281699547 0.769136226420716 -2.96318215423875" />
    <parent
      link="tensegrity" />
    <child
      link="tightener8" />
    <axis
      xyz="0 0 0" />
  </joint>
  <link
    name="tightener9">
    <inertial>
      <origin
        xyz="0.0352544256850752 0.00483663408845669 0.00519745259179438"
        rpy="0 0 0" />
      <mass
        value="0.00856463882730582" />
      <inertia
        ixx="9.48340756137E-07"
        ixy="4.66670079537861E-07"
        ixz="5.0146728722653E-07"
        iyy="3.09044692123597E-06"
        iyz="1.90237191683974E-07"
        izz="2.84368718796681E-06" />
    </inertial>
    <visual>
      <origin
        xyz="0 0 0"
        rpy="0 0 0" />
      <geometry>
        <mesh
          filename="package://tensegrity/meshes/tightener9.STL" />
      </geometry>
      <material
        name="">
        <color
          rgba="0.792156862745098 0.819607843137255 0.933333333333333 1" />
      </material>
    </visual>
    <collision>
      <origin
        xyz="0 0 0"
        rpy="0 0 0" />
      <geometry>
        <mesh
          filename="package://tensegrity/meshes/tightener9.STL" />
      </geometry>
    </collision>
  </link>
  <joint
    name="tightener9"
    type="fixed">
    <origin
      xyz="0.374418975757055 -0.134685129399173 1.34870291695999"
      rpy="0.785398163397445 0.181319774401485 1.5707963267949" />
    <parent
      link="tensegrity" />
    <child
      link="tightener9" />
    <axis
      xyz="0 0 0" />
  </joint>
  <link
    name="detach1">
    <inertial>
      <origin
        xyz="0.0016167294130276 0.00336313260997942 -8.8590788758669E-05"
        rpy="0 0 0" />
      <mass
        value="0.00144131652160447" />
      <inertia
        ixx="2.70919111337063E-08"
        ixy="8.31072147902913E-09"
        ixz="-3.60183626082554E-10"
        iyy="7.19839637780113E-08"
        iyz="-9.28387661696961E-11"
        izz="7.6586247123843E-08" />
    </inertial>
    <visual>
      <origin
        xyz="0 0 0"
        rpy="0 0 0" />
      <geometry>
        <mesh
          filename="package://tensegrity/meshes/detach1.STL" />
      </geometry>
      <material
        name="">
        <color
          rgba="0.792156862745098 0.819607843137255 0.933333333333333 1" />
      </material>
    </visual>
    <collision>
      <origin
        xyz="0 0 0"
        rpy="0 0 0" />
      <geometry>
        <mesh
          filename="package://tensegrity/meshes/detach1.STL" />
      </geometry>
    </collision>
  </link>
  <joint
    name="detach1"
    type="fixed">
    <origin
      xyz="0.0210000000000689 0.380483606557384 1.49506967213115"
      rpy="0 -0.181319774401501 -1.5707963267949" />
    <parent
      link="tensegrity" />
    <child
      link="detach1" />
    <axis
      xyz="0 0 0" />
  </joint>
  <link
    name="detach2">
    <inertial>
      <origin
        xyz="0.00161672941302771 0.00336313260997922 -8.85907887587523E-05"
        rpy="0 0 0" />
      <mass
        value="0.00144131652160448" />
      <inertia
        ixx="2.70919111337066E-08"
        ixy="8.31072147902925E-09"
        ixz="-3.60183626082382E-10"
        iyy="7.19839637780122E-08"
        iyz="-9.2838766169669E-11"
        izz="7.65862471238439E-08" />
    </inertial>
    <visual>
      <origin
        xyz="0 0 0"
        rpy="0 0 0" />
      <geometry>
        <mesh
          filename="package://tensegrity/meshes/detach2.STL" />
      </geometry>
      <material
        name="">
        <color
          rgba="0.792156862745098 0.819607843137255 0.933333333333333 1" />
      </material>
    </visual>
    <collision>
      <origin
        xyz="0 0 0"
        rpy="0 0 0" />
      <geometry>
        <mesh
          filename="package://tensegrity/meshes/detach2.STL" />
      </geometry>
    </collision>
  </link>
  <joint
    name="detach2"
    type="fixed">
    <origin
      xyz="-0.412814873975346 0.0389266585893259 1.30537268321449"
      rpy="1.31710983659433 -0.769136226420713 0.178410499351047" />
    <parent
      link="tensegrity" />
    <child
      link="detach2" />
    <axis
      xyz="0 0 0" />
  </joint>
  <link
    name="detach3">
    <inertial>
      <origin
        xyz="0.0016167294130276 0.00336313260997967 -8.85907887587817E-05"
        rpy="0 0 0" />
      <mass
        value="0.00144131652160448" />
      <inertia
        ixx="2.70919111337065E-08"
        ixy="8.31072147902936E-09"
        ixz="-3.60183626082399E-10"
        iyy="7.19839637780121E-08"
        iyz="-9.28387661697436E-11"
        izz="7.65862471238439E-08" />
    </inertial>
    <visual>
      <origin
        xyz="0 0 0"
        rpy="0 0 0" />
      <geometry>
        <mesh
          filename="package://tensegrity/meshes/detach3.STL" />
      </geometry>
      <material
        name="">
        <color
          rgba="0.792156862745098 0.819607843137255 0.933333333333333 1" />
      </material>
    </visual>
    <collision>
      <origin
        xyz="0 0 0"
        rpy="0 0 0" />
      <geometry>
        <mesh
          filename="package://tensegrity/meshes/detach3.STL" />
      </geometry>
    </collision>
  </link>
  <joint
    name="detach3"
    type="fixed">
    <origin
      xyz="-0.0144999999999317 -0.354442622950813 1.63438114754098"
      rpy="1.5707963267949 0.181319774401488 1.5707963267949" />
    <parent
      link="tensegrity" />
    <child
      link="detach3" />
    <axis
      xyz="0 0 0" />
  </joint>
  <link
    name="detach4">
    <inertial>
      <origin
        xyz="0.0016167294130276 0.00336313260997922 -8.85907887587523E-05"
        rpy="0 0 0" />
      <mass
        value="0.00144131652160448" />
      <inertia
        ixx="2.70919111337065E-08"
        ixy="8.31072147902907E-09"
        ixz="-3.6018362608249E-10"
        iyy="7.19839637780115E-08"
        iyz="-9.28387661697079E-11"
        izz="7.65862471238433E-08" />
    </inertial>
    <visual>
      <origin
        xyz="0 0 0"
        rpy="0 0 0" />
      <geometry>
        <mesh
          filename="package://tensegrity/meshes/detach4.STL" />
      </geometry>
      <material
        name="">
        <color
          rgba="0.792156862745098 0.819607843137255 0.933333333333333 1" />
      </material>
    </visual>
    <collision>
      <origin
        xyz="0 0 0"
        rpy="0 0 0" />
      <geometry>
        <mesh
          filename="package://tensegrity/meshes/detach4.STL" />
      </geometry>
    </collision>
  </link>
  <joint
    name="detach4"
    type="fixed">
    <origin
      xyz="-0.319830332249315 0.0252025595563105 1.40242305212534"
      rpy="1.31710983659434 -0.769136226420714 0.178410499351044" />
    <parent
      link="tensegrity" />
    <child
      link="detach4" />
    <axis
      xyz="0 0 0" />
  </joint>
  <link
    name="detach5">
    <inertial>
      <origin
        xyz="0.0016167294130276 0.00336313260997942 -8.85907887584469E-05"
        rpy="0 0 0" />
      <mass
        value="0.00144131652160448" />
      <inertia
        ixx="2.70919111337067E-08"
        ixy="8.31072147902927E-09"
        ixz="-3.60183626082365E-10"
        iyy="7.19839637780114E-08"
        iyz="-9.28387661695706E-11"
        izz="7.65862471238431E-08" />
    </inertial>
    <visual>
      <origin
        xyz="0 0 0"
        rpy="0 0 0" />
      <geometry>
        <mesh
          filename="package://tensegrity/meshes/detach5.STL" />
      </geometry>
      <material
        name="">
        <color
          rgba="0.792156862745098 0.819607843137255 0.933333333333333 1" />
      </material>
    </visual>
    <collision>
      <origin
        xyz="0 0 0"
        rpy="0 0 0" />
      <geometry>
        <mesh
          filename="package://tensegrity/meshes/detach5.STL" />
      </geometry>
    </collision>
  </link>
  <joint
    name="detach5"
    type="fixed">
    <origin
      xyz="0.11928297886751 0.098813098096445 1.82888962598058"
      rpy="0.253686490200554 0.769136226420711 -2.96318215423876" />
    <parent
      link="tensegrity" />
    <child
      link="detach5" />
    <axis
      xyz="0 0 0" />
  </joint>
  <link
    name="detach6">
    <inertial>
      <origin
        xyz="0.00161672941302737 0.00336313260997967 -8.859078875878E-05"
        rpy="0 0 0" />
      <mass
        value="0.00144131652160448" />
      <inertia
        ixx="2.70919111337065E-08"
        ixy="8.31072147902934E-09"
        ixz="-3.60183626082424E-10"
        iyy="7.19839637780119E-08"
        iyz="-9.28387661697462E-11"
        izz="7.65862471238437E-08" />
    </inertial>
    <visual>
      <origin
        xyz="0 0 0"
        rpy="0 0 0" />
      <geometry>
        <mesh
          filename="package://tensegrity/meshes/detach6.STL" />
      </geometry>
      <material
        name="">
        <color
          rgba="0.792156862745098 0.819607843137255 0.933333333333333 1" />
      </material>
    </visual>
    <collision>
      <origin
        xyz="0 0 0"
        rpy="0 0 0" />
      <geometry>
        <mesh
          filename="package://tensegrity/meshes/detach6.STL" />
      </geometry>
    </collision>
  </link>
  <joint
    name="detach6"
    type="fixed">
    <origin
      xyz="0.0165000000000686 -0.225098360655731 1.61066803278689"
      rpy="1.5707963267949 0.181319774401488 1.5707963267949" />
    <parent
      link="tensegrity" />
    <child
      link="detach6" />
    <axis
      xyz="0 0 0" />
  </joint>
  <link
    name="detach7">
    <inertial>
      <origin
        xyz="0.00161672941302737 0.00336313260997945 -8.85907887593906E-05"
        rpy="0 0 0" />
      <mass
        value="0.00144131652160447" />
      <inertia
        ixx="2.70919111337063E-08"
        ixy="8.310721479029E-09"
        ixz="-3.60183626082447E-10"
        iyy="7.19839637780114E-08"
        iyz="-9.28387661697302E-11"
        izz="7.65862471238431E-08" />
    </inertial>
    <visual>
      <origin
        xyz="0 0 0"
        rpy="0 0 0" />
      <geometry>
        <mesh
          filename="package://tensegrity/meshes/detach7.STL" />
      </geometry>
      <material
        name="">
        <color
          rgba="0.792156862745098 0.819607843137255 0.933333333333333 1" />
      </material>
    </visual>
    <collision>
      <origin
        xyz="0 0 0"
        rpy="0 0 0" />
      <geometry>
        <mesh
          filename="package://tensegrity/meshes/detach7.STL" />
      </geometry>
    </collision>
  </link>
  <joint
    name="detach7"
    type="fixed">
    <origin
      xyz="-0.0185202625483078 -0.0321606188160409 1.75498753373061"
      rpy="1.31710983659432 0.769136226420714 -0.178410499351051" />
    <parent
      link="tensegrity" />
    <child
      link="detach7" />
    <axis
      xyz="0 0 0" />
  </joint>
  <link
    name="detach8">
    <inertial>
      <origin
        xyz="0.00161672941302782 0.00336313260997922 -8.859078875878E-05"
        rpy="0 0 0" />
      <mass
        value="0.00144131652160448" />
      <inertia
        ixx="2.70919111337065E-08"
        ixy="8.31072147902908E-09"
        ixz="-3.60183626082449E-10"
        iyy="7.19839637780115E-08"
        iyz="-9.28387661697137E-11"
        izz="7.65862471238432E-08" />
    </inertial>
    <visual>
      <origin
        xyz="0 0 0"
        rpy="0 0 0" />
      <geometry>
        <mesh
          filename="package://tensegrity/meshes/detach8.STL" />
      </geometry>
      <material
        name="">
        <color
          rgba="0.792156862745098 0.819607843137255 0.933333333333333 1" />
      </material>
    </visual>
    <collision>
      <origin
        xyz="0 0 0"
        rpy="0 0 0" />
      <geometry>
        <mesh
          filename="package://tensegrity/meshes/detach8.STL" />
      </geometry>
    </collision>
  </link>
  <joint
    name="detach8"
    type="fixed">
    <origin
      xyz="-0.111504804274339 0.0150988887083267 1.84085757477261"
      rpy="1.31710983659432 0.769136226420715 -0.178410499351043" />
    <parent
      link="tensegrity" />
    <child
      link="detach8" />
    <axis
      xyz="0 0 0" />
  </joint>
  <link
    name="detach9">
    <inertial>
      <origin
        xyz="0.00161672941302771 0.00336313260997945 -8.8590788758891E-05"
        rpy="0 0 0" />
      <mass
        value="0.00144131652160448" />
      <inertia
        ixx="2.70919111337066E-08"
        ixy="8.31072147902909E-09"
        ixz="-3.60183626082305E-10"
        iyy="7.19839637780123E-08"
        iyz="-9.28387661696384E-11"
        izz="7.65862471238439E-08" />
    </inertial>
    <visual>
      <origin
        xyz="0 0 0"
        rpy="0 0 0" />
      <geometry>
        <mesh
          filename="package://tensegrity/meshes/detach9.STL" />
      </geometry>
      <material
        name="">
        <color
          rgba="0.792156862745098 0.819607843137255 0.933333333333333 1" />
      </material>
    </visual>
    <collision>
      <origin
        xyz="0 0 0"
        rpy="0 0 0" />
      <geometry>
        <mesh
          filename="package://tensegrity/meshes/detach9.STL" />
      </geometry>
    </collision>
  </link>
  <joint
    name="detach9"
    type="fixed">
    <origin
      xyz="0.414229087537839 -0.115771215902692 1.32388427689438"
      rpy="0.253686490200553 -0.769136226420708 2.96318215423877" />
    <parent
      link="tensegrity" />
    <child
      link="detach9" />
    <axis
      xyz="0 0 0" />
  </joint>
  <link
    name="attach2">
    <inertial>
      <origin
        xyz="5.55111512312578E-17 0.00040711367005164 0.000188401460229359"
        rpy="0 0 0" />
      <mass
        value="0.000125397117258051" />
      <inertia
        ixx="5.17034833783094E-09"
        ixy="-1.43044084834854E-23"
        ixz="1.03397576569128E-24"
        iyy="1.149750316004E-10"
        iyz="-9.61806045495267E-12"
        izz="5.17479932232886E-09" />
    </inertial>
    <visual>
      <origin
        xyz="0 0 0"
        rpy="0 0 0" />
      <geometry>
        <mesh
          filename="package://tensegrity/meshes/attach2.STL" />
      </geometry>
      <material
        name="">
        <color
          rgba="0.792156862745098 0.819607843137255 0.933333333333333 1" />
      </material>
    </visual>
    <collision>
      <origin
        xyz="0 0 0"
        rpy="0 0 0" />
      <geometry>
        <mesh
          filename="package://tensegrity/meshes/attach2.STL" />
      </geometry>
    </collision>
  </link>
  <joint
    name="attach2"
    type="fixed">
    <origin
      xyz="-0.0304246212023898 0.621142144807008 1.46713897167455"
      rpy="-2.35619449019234 -0.181319774401499 -1.5707963267949" />
    <parent
      link="tensegrity" />
    <child
      link="attach2" />
    <axis
      xyz="0 0 0" />
  </joint>
  <link
    name="attach3">
    <inertial>
      <origin
        xyz="0 0.000407113670051862 0.000188401460229803"
        rpy="0 0 0" />
      <mass
        value="0.000125397117258047" />
      <inertia
        ixx="5.17034833783086E-09"
        ixy="4.29544229223704E-23"
        ixz="1.31831910125639E-24"
        iyy="1.14975031600392E-10"
        iyz="-9.61806045497898E-12"
        izz="5.17479932232878E-09" />
    </inertial>
    <visual>
      <origin
        xyz="0 0 0"
        rpy="0 0 0" />
      <geometry>
        <mesh
          filename="package://tensegrity/meshes/attach3.STL" />
      </geometry>
      <material
        name="">
        <color
          rgba="0.792156862745098 0.819607843137255 0.933333333333333 1" />
      </material>
    </visual>
    <collision>
      <origin
        xyz="0 0 0"
        rpy="0 0 0" />
      <geometry>
        <mesh
          filename="package://tensegrity/meshes/attach3.STL" />
      </geometry>
    </collision>
  </link>
  <joint
    name="attach3"
    type="fixed">
    <origin
      xyz="-0.596432559529653 -0.0374265613533095 1.14911892837741"
      rpy="-2.6098809803929 -0.769136226420706 0.178410499351035" />
    <parent
      link="tensegrity" />
    <child
      link="attach3" />
    <axis
      xyz="0 0 0" />
  </joint>
  <link
    name="attach4">
    <inertial>
      <origin
        xyz="2.22044604925031E-16 0.000407113670051862 0.000188401460229359"
        rpy="0 0 0" />
      <mass
        value="0.00012539711725805" />
      <inertia
        ixx="5.17034833783088E-09"
        ixy="-5.99956360106698E-23"
        ixz="-4.70458973389534E-24"
        iyy="1.14975031600397E-10"
        iyz="-9.61806045494315E-12"
        izz="5.1747993223288E-09" />
    </inertial>
    <visual>
      <origin
        xyz="0 0 0"
        rpy="0 0 0" />
      <geometry>
        <mesh
          filename="package://tensegrity/meshes/attach4.STL" />
      </geometry>
      <material
        name="">
        <color
          rgba="0.792156862745098 0.819607843137255 0.933333333333333 1" />
      </material>
    </visual>
    <collision>
      <origin
        xyz="0 0 0"
        rpy="0 0 0" />
      <geometry>
        <mesh
          filename="package://tensegrity/meshes/attach4.STL" />
      </geometry>
    </collision>
  </link>
  <joint
    name="attach4"
    type="fixed">
    <origin
      xyz="-0.323406761076112 0.0558598630161561 1.97488089887448"
      rpy="0.531711673196865 0.769136226420715 -0.178410499351044" />
    <parent
      link="tensegrity" />
    <child
      link="attach4" />
    <axis
      xyz="0 0 0" />
  </joint>
  <link
    name="attach5">
    <inertial>
      <origin
        xyz="-5.55111512312578E-17 0.00040711367005164 0.000188401460229581"
        rpy="0 0 0" />
      <mass
        value="0.000125397117258046" />
      <inertia
        ixx="5.17034833783085E-09"
        ixy="1.29319672132436E-23"
        ixz="-1.60266243682149E-24"
        iyy="1.1497503160039E-10"
        iyz="-9.61806045499444E-12"
        izz="5.17479932232877E-09" />
    </inertial>
    <visual>
      <origin
        xyz="0 0 0"
        rpy="0 0 0" />
      <geometry>
        <mesh
          filename="package://tensegrity/meshes/attach5.STL" />
      </geometry>
      <material
        name="">
        <color
          rgba="0.792156862745098 0.819607843137255 0.933333333333333 1" />
      </material>
    </visual>
    <collision>
      <origin
        xyz="0 0 0"
        rpy="0 0 0" />
      <geometry>
        <mesh
          filename="package://tensegrity/meshes/attach5.STL" />
      </geometry>
    </collision>
  </link>
  <joint
    name="attach5"
    type="fixed">
    <origin
      xyz="0.0324246212025278 0.621142144807008 1.46713897167455"
      rpy="2.35619449019234 -0.181319774401488 -1.57079632679491" />
    <parent
      link="tensegrity" />
    <child
      link="attach5" />
    <axis
      xyz="0 0 0" />
  </joint>
  <link
    name="attach6">
    <inertial>
      <origin
        xyz="-5.55111512312578E-17 0.00040711367005164 0.000188401460229581"
        rpy="0 0 0" />
      <mass
        value="0.000125397117258046" />
      <inertia
        ixx="5.17034833783083E-09"
        ixy="6.12226744388613E-23"
        ixz="-6.72084247699335E-25"
        iyy="1.14975031600387E-10"
        iyz="-9.61806045499397E-12"
        izz="5.17479932232875E-09" />
    </inertial>
    <visual>
      <origin
        xyz="0 0 0"
        rpy="0 0 0" />
      <geometry>
        <mesh
          filename="package://tensegrity/meshes/attach6.STL" />
      </geometry>
      <material
        name="">
        <color
          rgba="0.792156862745098 0.819607843137255 0.933333333333333 1" />
      </material>
    </visual>
    <collision>
      <origin
        xyz="0 0 0"
        rpy="0 0 0" />
      <geometry>
        <mesh
          filename="package://tensegrity/meshes/attach6.STL" />
      </geometry>
    </collision>
  </link>
  <joint
    name="attach6"
    type="fixed">
    <origin
      xyz="0.596432559529791 -0.15580378141051 1.16887954624718"
      rpy="2.60988098039293 -0.769136226420717 2.96318215423874" />
    <parent
      link="tensegrity" />
    <child
      link="attach6" />
    <axis
      xyz="0 0 0" />
  </joint>
  <link
    name="attach7">
    <inertial>
      <origin
        xyz="1.11022302462516E-16 0.00040711367005164 0.000188401460229581"
        rpy="0 0 0" />
      <mass
        value="0.000125397117258045" />
      <inertia
        ixx="5.17034833783084E-09"
        ixy="-1.32970899055033E-23"
        ixz="6.72084247699335E-25"
        iyy="1.14975031600385E-10"
        iyz="-9.61806045499364E-12"
        izz="5.17479932232877E-09" />
    </inertial>
    <visual>
      <origin
        xyz="0 0 0"
        rpy="0 0 0" />
      <geometry>
        <mesh
          filename="package://tensegrity/meshes/attach7.STL" />
      </geometry>
      <material
        name="">
        <color
          rgba="0.792156862745098 0.819607843137255 0.933333333333333 1" />
      </material>
    </visual>
    <collision>
      <origin
        xyz="0 0 0"
        rpy="0 0 0" />
      <geometry>
        <mesh
          filename="package://tensegrity/meshes/attach7.STL" />
      </geometry>
    </collision>
  </link>
  <joint
    name="attach7"
    type="fixed">
    <origin
      xyz="-0.0304246212023898 -0.596562773225779 1.69038487331389"
      rpy="2.35619449019234 0.181319774401488 1.57079632679491" />
    <parent
      link="tensegrity" />
    <child
      link="attach7" />
    <axis
      xyz="0 0 0" />
  </joint>
  <link
    name="attach8">
    <inertial>
      <origin
        xyz="2.22044604925031E-16 0.00040711367005164 0.000188401460229803"
        rpy="0 0 0" />
      <mass
        value="0.00012539711725805" />
      <inertia
        ixx="5.17034833783084E-09"
        ixy="7.80013546179032E-23"
        ixz="2.71418638493962E-24"
        iyy="1.149750316004E-10"
        iyz="-9.61806045491666E-12"
        izz="5.17479932232876E-09" />
    </inertial>
    <visual>
      <origin
        xyz="0 0 0"
        rpy="0 0 0" />
      <geometry>
        <mesh
          filename="package://tensegrity/meshes/attach8.STL" />
      </geometry>
      <material
        name="">
        <color
          rgba="0.792156862745098 0.819607843137255 0.933333333333333 1" />
      </material>
    </visual>
    <collision>
      <origin
        xyz="0 0 0"
        rpy="0 0 0" />
      <geometry>
        <mesh
          filename="package://tensegrity/meshes/attach8.STL" />
      </geometry>
    </collision>
  </link>
  <joint
    name="attach8"
    type="fixed">
    <origin
      xyz="0.278965635579294 0.120432129567981 2.0101663334026"
      rpy="2.6098809803929 0.769136226420707 -2.96318215423875" />
    <parent
      link="tensegrity" />
    <child
      link="attach8" />
    <axis
      xyz="0 0 0" />
  </joint>
  <link
    name="attach9">
    <inertial>
      <origin
        xyz="0 0.000407113670051751 0.00018840146022947"
        rpy="0 0 0" />
      <mass
        value="0.000125397117258047" />
      <inertia
        ixx="5.17034833783084E-09"
        ixy="2.48154183765908E-24"
        ixz="-2.42984304937452E-24"
        iyy="1.14975031600392E-10"
        iyz="-9.61806045498024E-12"
        izz="5.17479932232877E-09" />
    </inertial>
    <visual>
      <origin
        xyz="0 0 0"
        rpy="0 0 0" />
      <geometry>
        <mesh
          filename="package://tensegrity/meshes/attach9.STL" />
      </geometry>
      <material
        name="">
        <color
          rgba="0.792156862745098 0.819607843137255 0.933333333333333 1" />
      </material>
    </visual>
    <collision>
      <origin
        xyz="0 0 0"
        rpy="0 0 0" />
      <geometry>
        <mesh
          filename="package://tensegrity/meshes/attach9.STL" />
      </geometry>
    </collision>
  </link>
  <joint
    name="attach9"
    type="fixed">
    <origin
      xyz="0.323406761076249 0.112418156117712 1.96645375094658"
      rpy="1.039084653598 0.76913622642071 -2.96318215423875" />
    <parent
      link="tensegrity" />
    <child
      link="attach9" />
    <axis
      xyz="0 0 0" />
  </joint>
  <link
    name="pulley1">
    <inertial>
      <origin
        xyz="0 -1.11022302462516E-16 2.05998412772246E-18"
        rpy="0 0 0" />
      <mass
        value="0.00115149136839394" />
      <inertia
        ixx="2.47202230080769E-08"
        ixy="-2.06795153138257E-24"
        ixz="-7.47137288100798E-25"
        iyy="2.47202230080769E-08"
        iyz="-2.91978752122891E-25"
        izz="2.72844075510586E-08" />
    </inertial>
    <visual>
      <origin
        xyz="0 0 0"
        rpy="0 0 0" />
      <geometry>
        <mesh
          filename="package://tensegrity/meshes/pulley1.STL" />
      </geometry>
      <material
        name="">
        <color
          rgba="0.792156862745098 0.819607843137255 0.933333333333333 1" />
      </material>
    </visual>
    <collision>
      <origin
        xyz="0 0 0"
        rpy="0 0 0" />
      <geometry>
        <mesh
          filename="package://tensegrity/meshes/pulley1.STL" />
      </geometry>
    </collision>
  </link>
  <joint
    name="pulley1"
    type="fixed">
    <origin
      xyz="0.000750000000068907 0.621786885245909 1.47065573770492"
      rpy="1.5707963267949 -1.35303842246507 -1.5707963267949" />
    <parent
      link="tensegrity" />
    <child
      link="pulley1" />
    <axis
      xyz="0 0 -1" />
  </joint>
  <link
    name="pulley2">
    <inertial>
      <origin
        xyz="0 0 0"
        rpy="0 0 0" />
      <mass
        value="0.00115149136839393" />
      <inertia
        ixx="2.47202230080765E-08"
        ixy="0"
        ixz="-7.67210018142933E-23"
        iyy="2.47202230080765E-08"
        iyz="7.98229291113672E-23"
        izz="2.7284407551058E-08" />
    </inertial>
    <visual>
      <origin
        xyz="0 0 0"
        rpy="0 0 0" />
      <geometry>
        <mesh
          filename="package://tensegrity/meshes/pulley2.STL" />
      </geometry>
      <material
        name="">
        <color
          rgba="0.792156862745098 0.819607843137255 0.933333333333333 1" />
      </material>
    </visual>
    <collision>
      <origin
        xyz="0 0 0"
        rpy="0 0 0" />
      <geometry>
        <mesh
          filename="package://tensegrity/meshes/pulley2.STL" />
      </geometry>
    </collision>
  </link>
  <joint
    name="pulley2"
    type="fixed">
    <origin
      xyz="-0.574388773476476 0.0239340226723326 1.11545830548531"
      rpy="0.631420863095884 0.532284485238218 -2.35588130681373" />
    <parent
      link="tensegrity" />
    <child
      link="pulley2" />
    <axis
      xyz="0 0 -1" />
  </joint>
  <link
    name="pulley3">
    <inertial>
      <origin
        xyz="5.55111512312578E-17 2.22044604925031E-16 -2.22044604925031E-16"
        rpy="0 0 0" />
      <mass
        value="0.00115149136839398" />
      <inertia
        ixx="2.4720223008078E-08"
        ixy="4.13590306276514E-24"
        ixz="-6.05909798695093E-23"
        iyy="2.47202230080779E-08"
        iyz="-4.83900658343521E-23"
        izz="2.72844075510596E-08" />
    </inertial>
    <visual>
      <origin
        xyz="0 0 0"
        rpy="0 0 0" />
      <geometry>
        <mesh
          filename="package://tensegrity/meshes/pulley3.STL" />
      </geometry>
      <material
        name="">
        <color
          rgba="0.792156862745098 0.819607843137255 0.933333333333333 1" />
      </material>
    </visual>
    <collision>
      <origin
        xyz="0 0 0"
        rpy="0 0 0" />
      <geometry>
        <mesh
          filename="package://tensegrity/meshes/pulley3.STL" />
      </geometry>
    </collision>
  </link>
  <joint
    name="pulley3"
    type="fixed">
    <origin
      xyz="-0.0339999999999311 -0.602184426229502 1.65972131147541"
      rpy="2.98449472353879 -0.0909133937987541 -0.520440071048006" />
    <parent
      link="tensegrity" />
    <child
      link="pulley3" />
    <axis
      xyz="0 0 -1" />
  </joint>
  <link
    name="pulley4">
    <inertial>
      <origin
        xyz="4.85722573273506E-17 -5.55111512312578E-17 0"
        rpy="0 0 0" />
      <mass
        value="0.00115149136839393" />
      <inertia
        ixx="2.47202230080765E-08"
        ixy="-3.30872245021211E-24"
        ixz="-5.27327640502555E-23"
        iyy="2.47202230080765E-08"
        iyz="1.06706299019341E-22"
        izz="2.7284407551058E-08" />
    </inertial>
    <visual>
      <origin
        xyz="0 0 0"
        rpy="0 0 0" />
      <geometry>
        <mesh
          filename="package://tensegrity/meshes/pulley4.STL" />
      </geometry>
      <material
        name="">
        <color
          rgba="0.792156862745098 0.819607843137255 0.933333333333333 1" />
      </material>
    </visual>
    <collision>
      <origin
        xyz="0 0 0"
        rpy="0 0 0" />
      <geometry>
        <mesh
          filename="package://tensegrity/meshes/pulley4.STL" />
      </geometry>
    </collision>
  </link>
  <joint
    name="pulley4"
    type="fixed">
    <origin
      xyz="-0.574035220085884 -0.0449821918735116 1.12773349887161"
      rpy="0.745639043009377 0.327890658213947 -2.08475010947139" />
    <parent
      link="tensegrity" />
    <child
      link="pulley4" />
    <axis
      xyz="0 0 -1" />
  </joint>
  <link
    name="pulley5">
    <inertial>
      <origin
        xyz="0 0 -2.77555756156289E-17"
        rpy="0 0 0" />
      <mass
        value="0.00115149136839394" />
      <inertia
        ixx="2.47202230080768E-08"
        ixy="1.78360819581747E-24"
        ixz="4.36337773121722E-23"
        iyy="2.47202230080768E-08"
        iyz="-3.80503081774393E-23"
        izz="2.72844075510585E-08" />
    </inertial>
    <visual>
      <origin
        xyz="0 0 0"
        rpy="0 0 0" />
      <geometry>
        <mesh
          filename="package://tensegrity/meshes/pulley5.STL" />
      </geometry>
      <material
        name="">
        <color
          rgba="0.792156862745098 0.819607843137255 0.933333333333333 1" />
      </material>
    </visual>
    <collision>
      <origin
        xyz="0 0 0"
        rpy="0 0 0" />
      <geometry>
        <mesh
          filename="package://tensegrity/meshes/pulley5.STL" />
      </geometry>
    </collision>
  </link>
  <joint
    name="pulley5"
    type="fixed">
    <origin
      xyz="0.276437460986239 0.152043395021608 2.00694124557237"
      rpy="1.36772787967172 0.464271853741143 -0.0919392370595982" />
    <parent
      link="tensegrity" />
    <child
      link="pulley5" />
    <axis
      xyz="0 0 1" />
  </joint>
  <link
    name="pulley6">
    <inertial>
      <origin
        xyz="0 0 0"
        rpy="0 0 0" />
      <mass
        value="0.00115149136839398" />
      <inertia
        ixx="2.47202230080779E-08"
        ixy="-1.03397576569128E-24"
        ixz="8.31316515615793E-23"
        iyy="2.47202230080779E-08"
        iyz="-1.2097516458588E-23"
        izz="2.72844075510596E-08" />
    </inertial>
    <visual>
      <origin
        xyz="0 0 0"
        rpy="0 0 0" />
      <geometry>
        <mesh
          filename="package://tensegrity/meshes/pulley6.STL" />
      </geometry>
      <material
        name="">
        <color
          rgba="0.792156862745098 0.819607843137255 0.933333333333333 1" />
      </material>
    </visual>
    <collision>
      <origin
        xyz="0 0 0"
        rpy="0 0 0" />
      <geometry>
        <mesh
          filename="package://tensegrity/meshes/pulley6.STL" />
      </geometry>
    </collision>
  </link>
  <joint
    name="pulley6"
    type="fixed">
    <origin
      xyz="0.0360000000000689 -0.602274590163928 1.65922950819672"
      rpy="3.12170686669581 0.180237919378081 1.4603031742211" />
    <parent
      link="tensegrity" />
    <child
      link="pulley6" />
    <axis
      xyz="0 0 -1" />
  </joint>
  <link
    name="pulley7">
    <inertial>
      <origin
        xyz="0 0 0"
        rpy="0 0 0" />
      <mass
        value="0.00115149136839393" />
      <inertia
        ixx="2.47202230080759E-08"
        ixy="0"
        ixz="1.34416849539867E-22"
        iyy="2.47202230080759E-08"
        iyz="2.50273834085575E-22"
        izz="2.72844075510581E-08" />
    </inertial>
    <visual>
      <origin
        xyz="0 0 0"
        rpy="0 0 0" />
      <geometry>
        <mesh
          filename="package://tensegrity/meshes/pulley7.STL" />
      </geometry>
      <material
        name="">
        <color
          rgba="0.792156862745098 0.819607843137255 0.933333333333333 1" />
      </material>
    </visual>
    <collision>
      <origin
        xyz="0 0 0"
        rpy="0 0 0" />
      <geometry>
        <mesh
          filename="package://tensegrity/meshes/pulley7.STL" />
      </geometry>
    </collision>
  </link>
  <joint
    name="pulley7"
    type="fixed">
    <origin
      xyz="-0.301362975022931 -0.00550072100945849 2.00854152176658"
      rpy="2.37738677488523 -0.271358663823428 -1.66506917334561" />
    <parent
      link="tensegrity" />
    <child
      link="pulley7" />
    <axis
      xyz="0 0 -1" />
  </joint>
  <link
    name="pulley8">
    <inertial>
      <origin
        xyz="0 0 -2.22044604925031E-16"
        rpy="0 0 0" />
      <mass
        value="0.00115149136839392" />
      <inertia
        ixx="2.47202230080764E-08"
        ixy="-4.13590306276514E-25"
        ixz="-6.61744490042422E-24"
        iyy="2.47202230080764E-08"
        iyz="4.63221143029696E-23"
        izz="2.72844075510578E-08" />
    </inertial>
    <visual>
      <origin
        xyz="0 0 0"
        rpy="0 0 0" />
      <geometry>
        <mesh
          filename="package://tensegrity/meshes/pulley8.STL" />
      </geometry>
      <material
        name="">
        <color
          rgba="0.792156862745098 0.819607843137255 0.933333333333333 1" />
      </material>
    </visual>
    <collision>
      <origin
        xyz="0 0 0"
        rpy="0 0 0" />
      <geometry>
        <mesh
          filename="package://tensegrity/meshes/pulley8.STL" />
      </geometry>
    </collision>
  </link>
  <joint
    name="pulley8"
    type="fixed">
    <origin
      xyz="-0.301009421632338 0.0634154935363862 1.99626632838028"
      rpy="0.780417755714485 0.206550528203247 1.54495729002601" />
    <parent
      link="tensegrity" />
    <child
      link="pulley8" />
    <axis
      xyz="0 0 1" />
  </joint>
  <link
    name="pulley9">
    <inertial>
      <origin
        xyz="-1.11022302462516E-16 -2.22044604925031E-16 -1.11022302462516E-16"
        rpy="0 0 0" />
      <mass
        value="0.00115149136839395" />
      <inertia
        ixx="2.47202230080769E-08"
        ixy="1.63372385733306E-25"
        ixz="-1.22497643335136E-22"
        iyy="2.47202230080769E-08"
        iyz="-1.13737334226041E-22"
        izz="2.72844075510587E-08" />
    </inertial>
    <visual>
      <origin
        xyz="0 0 0"
        rpy="0 0 0" />
      <geometry>
        <mesh
          filename="package://tensegrity/meshes/pulley9.STL" />
      </geometry>
      <material
        name="">
        <color
          rgba="0.792156862745098 0.819607843137255 0.933333333333333 1" />
      </material>
    </visual>
    <collision>
      <origin
        xyz="0 0 0"
        rpy="0 0 0" />
      <geometry>
        <mesh
          filename="package://tensegrity/meshes/pulley9.STL" />
      </geometry>
    </collision>
  </link>
  <joint
    name="pulley9"
    type="fixed">
    <origin
      xyz="0.598960734122845 -0.124192515956886 1.16565445841695"
      rpy="1.3894765523934 0 0" />
    <parent
      link="tensegrity" />
    <child
      link="pulley9" />
    <axis
      xyz="0 0 1" />
  </joint>
  <link
    name="mid1">
    <inertial>
      <origin
        xyz="0.0016167294130276 0.00336313260997943 -8.85907887587809E-05"
        rpy="0 0 0" />
      <mass
        value="0.00144131652160448" />
      <inertia
        ixx="2.70919111337064E-08"
        ixy="8.3107214790291E-09"
        ixz="-3.60183626082441E-10"
        iyy="7.19839637780115E-08"
        iyz="-9.28387661697139E-11"
        izz="7.65862471238432E-08" />
    </inertial>
    <visual>
      <origin
        xyz="0 0 0"
        rpy="0 0 0" />
      <geometry>
        <mesh
          filename="package://tensegrity/meshes/mid1.STL" />
      </geometry>
      <material
        name="">
        <color
          rgba="0.792156862745098 0.819607843137255 0.933333333333333 1" />
      </material>
    </visual>
    <collision>
      <origin
        xyz="0 0 0"
        rpy="0 0 0" />
      <geometry>
        <mesh
          filename="package://tensegrity/meshes/mid1.STL" />
      </geometry>
    </collision>
  </link>
  <joint
    name="mid1"
    type="fixed">
    <origin
      xyz="0 -0.0407921561087422 1.288"
      rpy="3.14159265358979 1.5707963267949 0" />
    <parent
      link="tensegrity" />
    <child
      link="mid1" />
    <axis
      xyz="0 0 0" />
  </joint>
  <link
    name="mid2">
    <inertial>
      <origin
        xyz="0.00161672941302782 0.00336313260997943 -8.8590788758787E-05"
        rpy="0 0 0" />
      <mass
        value="0.00144131652160447" />
      <inertia
        ixx="2.70919111337064E-08"
        ixy="8.31072147902904E-09"
        ixz="-3.60183626082548E-10"
        iyy="7.19839637780113E-08"
        iyz="-9.28387661697368E-11"
        izz="7.6586247123843E-08" />
    </inertial>
    <visual>
      <origin
        xyz="0 0 0"
        rpy="0 0 0" />
      <geometry>
        <mesh
          filename="package://tensegrity/meshes/mid2.STL" />
      </geometry>
      <material
        name="">
        <color
          rgba="0.792156862745098 0.819607843137255 0.933333333333333 1" />
      </material>
    </visual>
    <collision>
      <origin
        xyz="0 0 0"
        rpy="0 0 0" />
      <geometry>
        <mesh
          filename="package://tensegrity/meshes/mid2.STL" />
      </geometry>
    </collision>
  </link>
  <joint
    name="mid2"
    type="fixed">
    <origin
      xyz="0.0353270434653114 -0.020396078054371 1.288"
      rpy="2.09439510239319 1.5707963267949 0" />
    <parent
      link="tensegrity" />
    <child
      link="mid2" />
    <axis
      xyz="0 0 0" />
  </joint>
  <link
    name="mid3">
    <inertial>
      <origin
        xyz="0.00161672941302737 0.00336313260997943 -8.8590788758787E-05"
        rpy="0 0 0" />
      <mass
        value="0.00144131652160447" />
      <inertia
        ixx="2.70919111337064E-08"
        ixy="8.31072147902903E-09"
        ixz="-3.60183626082501E-10"
        iyy="7.19839637780113E-08"
        iyz="-9.28387661697203E-11"
        izz="7.65862471238429E-08" />
    </inertial>
    <visual>
      <origin
        xyz="0 0 0"
        rpy="0 0 0" />
      <geometry>
        <mesh
          filename="package://tensegrity/meshes/mid3.STL" />
      </geometry>
      <material
        name="">
        <color
          rgba="0.792156862745098 0.819607843137255 0.933333333333333 1" />
      </material>
    </visual>
    <collision>
      <origin
        xyz="0 0 0"
        rpy="0 0 0" />
      <geometry>
        <mesh
          filename="package://tensegrity/meshes/mid3.STL" />
      </geometry>
    </collision>
  </link>
  <joint
    name="mid3"
    type="fixed">
    <origin
      xyz="-0.0353270434653113 0.0203960780543712 1.288"
      rpy="1.0471975511966 1.5707963267949 0" />
    <parent
      link="tensegrity" />
    <child
      link="mid3" />
    <axis
      xyz="0 0 0" />
  </joint>
  <link
    name="mid4">
    <inertial>
      <origin
        xyz="0.0016167294130276 0.00336313260997943 -8.85907887587786E-05"
        rpy="0 0 0" />
      <mass
        value="0.00144131652160448" />
      <inertia
        ixx="2.70919111337064E-08"
        ixy="8.31072147902908E-09"
        ixz="-3.60183626082439E-10"
        iyy="7.19839637780115E-08"
        iyz="-9.28387661697143E-11"
        izz="7.65862471238432E-08" />
    </inertial>
    <visual>
      <origin
        xyz="0 0 0"
        rpy="0 0 0" />
      <geometry>
        <mesh
          filename="package://tensegrity/meshes/mid4.STL" />
      </geometry>
      <material
        name="">
        <color
          rgba="0.792156862745098 0.819607843137255 0.933333333333333 1" />
      </material>
    </visual>
    <collision>
      <origin
        xyz="0 0 0"
        rpy="0 0 0" />
      <geometry>
        <mesh
          filename="package://tensegrity/meshes/mid4.STL" />
      </geometry>
    </collision>
  </link>
  <joint
    name="mid4"
    type="fixed">
    <origin
      xyz="0 0.0407921561087424 1.288"
      rpy="0 1.5707963267949 0" />
    <parent
      link="tensegrity" />
    <child
      link="mid4" />
    <axis
      xyz="0 0 0" />
  </joint>
  <link
    name="mid5">
    <inertial>
      <origin
        xyz="0.00161672941302782 0.00336313260997942 -8.85907887587835E-05"
        rpy="0 0 0" />
      <mass
        value="0.00144131652160448" />
      <inertia
        ixx="2.70919111337064E-08"
        ixy="8.31072147902912E-09"
        ixz="-3.60183626082497E-10"
        iyy="7.19839637780115E-08"
        iyz="-9.28387661697335E-11"
        izz="7.65862471238432E-08" />
    </inertial>
    <visual>
      <origin
        xyz="0 0 0"
        rpy="0 0 0" />
      <geometry>
        <mesh
          filename="package://tensegrity/meshes/mid5.STL" />
      </geometry>
      <material
        name="">
        <color
          rgba="0.792156862745098 0.819607843137255 0.933333333333333 1" />
      </material>
    </visual>
    <collision>
      <origin
        xyz="0 0 0"
        rpy="0 0 0" />
      <geometry>
        <mesh
          filename="package://tensegrity/meshes/mid5.STL" />
      </geometry>
    </collision>
  </link>
  <joint
    name="mid5"
    type="fixed">
    <origin
      xyz="0.0353270434653114 0.0203960780543712 1.288"
      rpy="1.0471975511966 1.5707963267949 0" />
    <parent
      link="tensegrity" />
    <child
      link="mid5" />
    <axis
      xyz="0 0 0" />
  </joint>
  <link
    name="mid6">
    <inertial>
      <origin
        xyz="0.00161672941302782 0.00336313260997943 -8.85907887587765E-05"
        rpy="0 0 0" />
      <mass
        value="0.00144131652160448" />
      <inertia
        ixx="2.70919111337064E-08"
        ixy="8.3107214790291E-09"
        ixz="-3.60183626082403E-10"
        iyy="7.19839637780115E-08"
        iyz="-9.2838766169717E-11"
        izz="7.65862471238432E-08" />
    </inertial>
    <visual>
      <origin
        xyz="0 0 0"
        rpy="0 0 0" />
      <geometry>
        <mesh
          filename="package://tensegrity/meshes/mid6.STL" />
      </geometry>
      <material
        name="">
        <color
          rgba="0.792156862745098 0.819607843137255 0.933333333333333 1" />
      </material>
    </visual>
    <collision>
      <origin
        xyz="0 0 0"
        rpy="0 0 0" />
      <geometry>
        <mesh
          filename="package://tensegrity/meshes/mid6.STL" />
      </geometry>
    </collision>
  </link>
  <joint
    name="mid6"
    type="fixed">
    <origin
      xyz="-0.0353270434653115 -0.0203960780543711 1.288"
      rpy="2.0943951023932 1.5707963267949 0" />
    <parent
      link="tensegrity" />
    <child
      link="mid6" />
    <axis
      xyz="0 0 0" />
  </joint>
  <link
    name="tendon1">
    <inertial>
      <origin
        xyz="3.99680288865056E-15 0.49022 3.33066907387547E-16"
        rpy="0 0 0" />
      <mass
        value="0.0123205724051423" />
      <inertia
        ixx="0.000986954435972712"
        ixy="8.79269168342227E-18"
        ixz="9.48676900924816E-20"
        iyy="2.46411448102221E-08"
        iyz="-3.45909561376813E-19"
        izz="0.000986954435972712" />
    </inertial>
    <visual>
      <origin
        xyz="0 0 0"
        rpy="0 0 0" />
      <geometry>
        <mesh
          filename="package://tensegrity/meshes/tendon1.STL" />
      </geometry>
      <material
        name="">
        <color
          rgba="0.792156862745098 0.819607843137255 0.933333333333333 1" />
      </material>
    </visual>
    <collision>
      <origin
        xyz="0 0 0"
        rpy="0 0 0" />
      <geometry>
        <mesh
          filename="package://tensegrity/meshes/tendon1.STL" />
      </geometry>
    </collision>
  </link>
  <joint
    name="tendon1"
    type="continuous">
    <origin
      xyz="0.0070000000000689 0.619377049180335 1.4741475409836"
      rpy="-2.05407776195157 1.2043856781213 1.75162768833035" />
    <parent
      link="tensegrity" />
    <child
      link="tendon1" />
    <axis
      xyz="0 -1 0" />
  </joint>
  <link
    name="tendon2">
    <inertial>
      <origin
        xyz="-1.11022302462516E-15 0.42479 1.22124532708767E-15"
        rpy="0 0 0" />
      <mass
        value="0.0106761371465473" />
      <inertia
        ixx="0.000642168026947843"
        ixy="-1.85410259557077E-18"
        ixz="8.13151629364128E-20"
        iyy="2.13522742930919E-08"
        iyz="1.64659565351541E-18"
        izz="0.000642168026947843" />
    </inertial>
    <visual>
      <origin
        xyz="0 0 0"
        rpy="0 0 0" />
      <geometry>
        <mesh
          filename="package://tensegrity/meshes/tendon2.STL" />
      </geometry>
      <material
        name="">
        <color
          rgba="0.792156862745098 0.819607843137255 0.933333333333333 1" />
      </material>
    </visual>
    <collision>
      <origin
        xyz="0 0 0"
        rpy="0 0 0" />
      <geometry>
        <mesh
          filename="package://tensegrity/meshes/tendon2.STL" />
      </geometry>
    </collision>
  </link>
  <joint
    name="tendon2"
    type="continuous">
    <origin
      xyz="-0.580575957811856 0.0272354977564193 1.11682998776229"
      rpy="0.542760383124674 0.679222116277311 -0.385370645633379" />
    <parent
      link="tensegrity" />
    <child
      link="tendon2" />
    <axis
      xyz="0 -1 0" />
  </joint>
  <link
    name="tendon3">
    <inertial>
      <origin
        xyz="-3.99680288865056E-15 0.472435 -8.60422844084496E-16"
        rpy="0 0 0" />
      <mass
        value="0.0118735866023895" />
      <inertia
        ixx="0.000883386251589463"
        ixy="-7.53057991837917E-18"
        ixz="-2.71050543121376E-20"
        iyy="2.3747173204747E-08"
        iyz="-9.75604938585868E-19"
        izz="0.000883386251589463" />
    </inertial>
    <visual>
      <origin
        xyz="0 0 0"
        rpy="0 0 0" />
      <geometry>
        <mesh
          filename="package://tensegrity/meshes/tendon3.STL" />
      </geometry>
      <material
        name="">
        <color
          rgba="0.792156862745098 0.819607843137255 0.933333333333333 1" />
      </material>
    </visual>
    <collision>
      <origin
        xyz="0 0 0"
        rpy="0 0 0" />
      <geometry>
        <mesh
          filename="package://tensegrity/meshes/tendon3.STL" />
      </geometry>
    </collision>
  </link>
  <joint
    name="tendon3"
    type="continuous">
    <origin
      xyz="-0.0369999999999311 -0.604098360655731 1.66591803278689"
      rpy="-1.97723117907901 -0.944746282793038 2.83859847552446" />
    <parent
      link="tensegrity" />
    <child
      link="tendon3" />
    <axis
      xyz="0 1 0" />
  </joint>
  <link
    name="tendon4">
    <inertial>
      <origin
        xyz="9.99200722162641E-16 0.44834 0"
        rpy="0 0 0" />
      <mass
        value="0.0112680132024836" />
      <inertia
        ixx="0.000755001038651735"
        ixy="1.45082228783616E-18"
        ixz="-3.3881317890172E-21"
        iyy="2.25360264049695E-08"
        iyz="-8.49886720367608E-21"
        izz="0.000755001038651735" />
    </inertial>
    <visual>
      <origin
        xyz="0 0 0"
        rpy="0 0 0" />
      <geometry>
        <mesh
          filename="package://tensegrity/meshes/tendon4.STL" />
      </geometry>
      <material
        name="">
        <color
          rgba="0.792156862745098 0.819607843137255 0.933333333333333 1" />
      </material>
    </visual>
    <collision>
      <origin
        xyz="0 0 0"
        rpy="0 0 0" />
      <geometry>
        <mesh
          filename="package://tensegrity/meshes/tendon4.STL" />
      </geometry>
    </collision>
  </link>
  <joint
    name="tendon4"
    type="continuous">
    <origin
      xyz="-0.572090676437616 -0.0490487333110664 1.12218872739419"
      rpy="1.440424684019 0.282232816368081 -0.0185464264423147" />
    <parent
      link="tensegrity" />
    <child
      link="tendon4" />
    <axis
      xyz="0 -1 0" />
  </joint>
  <link
    name="tendon5">
    <inertial>
      <origin
        xyz="-1.99840144432528E-15 0.385484999999999 -1.11022302462516E-15"
        rpy="0 0 0" />
      <mass
        value="0.00968829475255249" />
      <inertia
        ixx="0.000479898975728608"
        ixy="-2.49620195965536E-18"
        ixz="0"
        iyy="1.93765895051269E-08"
        iyz="-1.73730262512675E-18"
        izz="0.000479898975728608" />
    </inertial>
    <visual>
      <origin
        xyz="0 0 0"
        rpy="0 0 0" />
      <geometry>
        <mesh
          filename="package://tensegrity/meshes/tendon5.STL" />
      </geometry>
      <material
        name="">
        <color
          rgba="0.792156862745098 0.819607843137255 0.933333333333333 1" />
      </material>
    </visual>
    <collision>
      <origin
        xyz="0 0 0"
        rpy="0 0 0" />
      <geometry>
        <mesh
          filename="package://tensegrity/meshes/tendon5.STL" />
      </geometry>
    </collision>
  </link>
  <joint
    name="tendon5"
    type="continuous">
    <origin
      xyz="0.276437460986242 0.158464199079938 2.01007744952691"
      rpy="-0.904840677620968 -0.402289800523352 0.935725152760631" />
    <parent
      link="tensegrity" />
    <child
      link="tendon5" />
    <axis
      xyz="0 1 0" />
  </joint>
  <link
    name="tendon6">
    <inertial>
      <origin
        xyz="1.11022302462516E-16 0.432875 2.22044604925031E-16"
        rpy="0 0 0" />
      <mass
        value="0.0108793353593815" />
      <inertia
        ixx="0.00067953694237937"
        ixy="9.63872208777416E-20"
        ixz="-2.71050543121376E-20"
        iyy="2.17586707186553E-08"
        iyz="-1.90689946611849E-19"
        izz="0.00067953694237937" />
    </inertial>
    <visual>
      <origin
        xyz="0 0 0"
        rpy="0 0 0" />
      <geometry>
        <mesh
          filename="package://tensegrity/meshes/tendon6.STL" />
      </geometry>
      <material
        name="">
        <color
          rgba="0.792156862745098 0.819607843137255 0.933333333333333 1" />
      </material>
    </visual>
    <collision>
      <origin
        xyz="0 0 0"
        rpy="0 0 0" />
      <geometry>
        <mesh
          filename="package://tensegrity/meshes/tendon6.STL" />
      </geometry>
    </collision>
  </link>
  <joint
    name="tendon6"
    type="continuous">
    <origin
      xyz="0.0387071067812556 -0.604225871714633 1.66522251792014"
      rpy="-0.843481301503022 0.696282568469085 -1.5232985820643" />
    <parent
      link="tensegrity" />
    <child
      link="tendon6" />
    <axis
      xyz="0 1 0" />
  </joint>
  <link
    name="tendon7">
    <inertial>
      <origin
        xyz="-1.11022302462516E-15 0.36037 -1.55431223447522E-15"
        rpy="0 0 0" />
      <mass
        value="0.00905708595659323" />
      <inertia
        ixx="0.000392079852948752"
        ixy="-7.23121291493857E-19"
        ixz="-3.3881317890172E-21"
        iyy="1.81141719132031E-08"
        iyz="-7.93473416181798E-19"
        izz="0.000392079852948752" />
    </inertial>
    <visual>
      <origin
        xyz="0 0 0"
        rpy="0 0 0" />
      <geometry>
        <mesh
          filename="package://tensegrity/meshes/tendon7.STL" />
      </geometry>
      <material
        name="">
        <color
          rgba="0.792156862745098 0.819607843137255 0.933333333333333 1" />
      </material>
    </visual>
    <collision>
      <origin
        xyz="0 0 0"
        rpy="0 0 0" />
      <geometry>
        <mesh
          filename="package://tensegrity/meshes/tendon7.STL" />
      </geometry>
    </collision>
  </link>
  <joint
    name="tendon7"
    type="continuous">
    <origin
      xyz="-0.307550159358307 -0.0088021960935663 2.0071698394896"
      rpy="-2.65608974352876 0.398388925164006 0.646068565378626" />
    <parent
      link="tensegrity" />
    <child
      link="tendon7" />
    <axis
      xyz="0 -1 0" />
  </joint>
  <link
    name="tendon8">
    <inertial>
      <origin
        xyz="-4.44089209850063E-16 0.291190000000001 1.94289029309402E-16"
        rpy="0 0 0" />
      <mass
        value="0.0073184029183905" />
      <inertia
        ixx="0.000206853721976681"
        ixy="2.27699713277485E-19"
        ixz="0"
        iyy="1.4636805836781E-08"
        iyz="8.16285609909939E-20"
        izz="0.000206853721976681" />
    </inertial>
    <visual>
      <origin
        xyz="0 0 0"
        rpy="0 0 0" />
      <geometry>
        <mesh
          filename="package://tensegrity/meshes/tendon8.STL" />
      </geometry>
      <material
        name="">
        <color
          rgba="0.792156862745098 0.819607843137255 0.933333333333333 1" />
      </material>
    </visual>
    <collision>
      <origin
        xyz="0 0 0"
        rpy="0 0 0" />
      <geometry>
        <mesh
          filename="package://tensegrity/meshes/tendon8.STL" />
      </geometry>
    </collision>
  </link>
  <joint
    name="tendon8"
    type="continuous">
    <origin
      xyz="-0.299064877984069 0.0674820349739192 2.0018110998577"
      rpy="0.182977508146443 1.49011189347165 -1.30905774743622" />
    <parent
      link="tensegrity" />
    <child
      link="tendon8" />
    <axis
      xyz="0 -1 0" />
  </joint>
  <link
    name="tendon9">
    <inertial>
      <origin
        xyz="-1.55431223447522E-15 4.25354196309513E-15 0.43739"
        rpy="0 0 0" />
      <mass
        value="0.0109928096860291" />
      <inertia
        ixx="0.000701022510825428"
        ixy="-4.06575814682064E-20"
        ixz="-2.22141483491193E-18"
        iyy="0.000701022510825428"
        iyz="6.0361251133888E-18"
        izz="2.19856193720755E-08" />
    </inertial>
    <visual>
      <origin
        xyz="0 0 0"
        rpy="0 0 0" />
      <geometry>
        <mesh
          filename="package://tensegrity/meshes/tendon9.STL" />
      </geometry>
      <material
        name="">
        <color
          rgba="0.792156862745098 0.819607843137255 0.933333333333333 1" />
      </material>
    </visual>
    <collision>
      <origin
        xyz="0 0 0"
        rpy="0 0 0" />
      <geometry>
        <mesh
          filename="package://tensegrity/meshes/tendon9.STL" />
      </geometry>
    </collision>
  </link>
  <joint
    name="tendon9"
    type="continuous">
    <origin
      xyz="0.603203374809965 -0.130340056940491 1.16678150759728"
      rpy="-0.157059449593044 -0.40457084948561 -0.346816167000894" />
    <parent
      link="tensegrity" />
    <child
      link="tendon9" />
    <axis
      xyz="0 0 -1" />
  </joint>
  <link
    name="attach1">
    <inertial>
      <origin
        xyz="5.55111512312578E-17 0.000407113670051862 0.00018840146022947"
        rpy="0 0 0" />
      <mass
        value="0.000125397117258048" />
      <inertia
        ixx="5.17034833783086E-09"
        ixy="-2.16327117228223E-24"
        ixz="-9.8227697740672E-25"
        iyy="1.14975031600396E-10"
        iyz="-9.61806045498377E-12"
        izz="5.17479932232878E-09" />
    </inertial>
    <visual>
      <origin
        xyz="0 0 0"
        rpy="0 0 0" />
      <geometry>
        <mesh
          filename="package://tensegrity/meshes/attach1.STL" />
      </geometry>
      <material
        name="">
        <color
          rgba="0.792156862745098 0.819607843137255 0.933333333333333 1" />
      </material>
    </visual>
    <collision>
      <origin
        xyz="0 0 0"
        rpy="0 0 0" />
      <geometry>
        <mesh
          filename="package://tensegrity/meshes/attach1.STL" />
      </geometry>
    </collision>
  </link>
  <joint
    name="attach1"
    type="fixed">
    <origin
      xyz="0.596432559529796 -0.0939848544548516 1.15754607630531"
      rpy="-2.10250799999178 -0.769136226420718 2.96318215423875" />
    <parent
      link="tensegrity" />
    <child
      link="attach1" />
    <axis
      xyz="0 0 0" />
  </joint>
</robot>